Workbook

Sheet INVOICE
A1: INVOICE
H5: インボイス作成日（Date): 24/11/2025
A7: 依頼住 (Shipper Address) | H7: Invoice No [Invoice No]
A9: MASUDA VINYL VIETNAM CO.,LTD
A10: LOT NO1 DONG VANG DINH TRAM INDUSTRIAL ZONE | H10: (原産国) Country of Origin | J10: (仕向先国名) Country of Destination
A11: NENH WARD BAC NINH PROVINCE
A12: TEL : 0204 3662 777 | H12: VIETNAM | J12: INDONESIA
A13: FAX : 0204 3662 825
H14: Invoice will be closed on delivery day and payment after 60days
A15: 荷受人(Consigneer)
A18: PT. Sumitronics Indonesia
A19: KAWASAN INDUSTRIAL EJIP PLOT 1E-2 SUKARESMI CIKARANG SELATAN | H19: 備考 (Remark):
A21: TEL :62-21-8975220 ext : 252 | H21: P | I21: 有償（Commerical Value)
A22: TAX ID: 001.558.251.3-056.000 | I22: 無償（No Commerical Value)
A24: From (発地国) | I24: 贈物（Gift)
A25: BACNINH VIETNAM | I25: 商品見本（ Sample, No Commercial Value )
A26: To (着地国) | I26: その他（Other)
A27: JAKARTA INDONESIA
A29: 品番 ( Part No) | D29: 品名 (Part Name) | E29: 注文書No PO No | F29: 単位 （Unit） | G29: 数量 （Quantity) | H29: 単価 （Unit Price） USD | J29: 合計 （Total Amount) USD
A33: 1 | B33: LDBA043800-2 | D33: =VLOOKUP(B33,データ!$B$3:$N$77,2,FALSE) -> RAIL TOP | E33: PHC-2025100007 | F33: =VLOOKUP(B33,データ!$B$3:$N$73,13,FALSE) -> pcs | G33: 300 | H33: =VLOOKUP(B33,データ!B2:D61,3,FALSE) -> 6.55 | J33: =H33*G33 -> 1965
A34: =A33+1 -> 2 | B34: LDBA043900-2 | D34: =VLOOKUP(B34,データ!$B$3:$N$77,2,FALSE) -> RAIL BOTTOM | E34: PHC-2025100007 | F34: =VLOOKUP(B34,データ!$B$3:$N$73,13,FALSE) -> pcs | G34: 300 | H34: =VLOOKUP(B34,データ!B3:D62,3,FALSE) -> 9.88 | J34: =H34*G34 -> 2964
A35: =A34+1 -> 3 | B35: LDBA044901-2 | D35: =VLOOKUP(B35,データ!$B$3:$N$77,2,FALSE) -> DOOR OUTER SASH R -S500 | E35: PHC-2025100019 | F35: =VLOOKUP(B35,データ!$B$3:$N$73,13,FALSE) -> pcs | G35: 329 | H35: =VLOOKUP(B35,データ!B4:D63,3,FALSE) -> 11.04 | J35: =H35*G35 -> 3632.16
A36: =A35+1 -> 4 | B36: LDBA045001-2 | D36: =VLOOKUP(B36,データ!$B$3:$N$77,2,FALSE) -> DOOR OUTER SASH L-S500 | E36: PHC-2025100019 | F36: =VLOOKUP(B36,データ!$B$3:$N$73,13,FALSE) -> pcs | G36: 331 | H36: =VLOOKUP(B36,データ!B5:D64,3,FALSE) -> 11.04 | J36: =H36*G36 -> 3654.24
A37: =A36+1 -> 5 | B37: LDBA045101-3 | D37: =VLOOKUP(B37,データ!$B$3:$N$77,2,FALSE) -> DOOR CENTER SASH-S500H | E37: PHC-2025100007 PHC-2025100019 | F37: =VLOOKUP(B37,データ!$B$3:$N$73,13,FALSE) -> pcs | G37: 640 | H37: =VLOOKUP(B37,データ!B6:D65,3,FALSE) -> 7.94 | J37: =H37*G37 -> 5081.6
A38: =A37+1 -> 6 | B38: LDBA053601-2 | D38: =VLOOKUP(B38,データ!$B$3:$N$77,2,FALSE) -> DOOR UPPER SASH L-S500H | E38: PHC-2025100019 | F38: =VLOOKUP(B38,データ!$B$3:$N$73,13,FALSE) -> pcs | G38: 300 | H38: =VLOOKUP(B38,データ!B7:D66,3,FALSE) -> 5.01 | J38: =H38*G38 -> 1503
A39: =A38+1 -> 7 | B39: LDBA064301-2 | D39: =VLOOKUP(B39,データ!$B$3:$N$77,2,FALSE) -> DOOR UPPER SASH R-S500H | E39: PHC-2025100007 | F39: =VLOOKUP(B39,データ!$B$3:$N$73,13,FALSE) -> pcs | G39: 300 | H39: =VLOOKUP(B39,データ!B8:D67,3,FALSE) -> 5.01 | J39: =H39*G39 -> 1503
A40: =A39+1 -> 8 | B40: LDBA053603-0 | D40: =VLOOKUP(B40,データ!$B$3:$N$77,2,FALSE) -> DOOR UPPER SASH L-S150H | E40: PHC-2025100019 | F40: =VLOOKUP(B40,データ!$B$3:$N$73,13,FALSE) -> pcs | G40: 300 | H40: =VLOOKUP(B40,データ!B9:D68,3,FALSE) -> 4.59 | J40: =H40*G40 -> 1377
A41: =A40+1 -> 9 | B41: LDBA064303-0 | D41: =VLOOKUP(B41,データ!$B$3:$N$77,2,FALSE) -> DOOR UPPER SASH R-S150H | E41: PHC-2025100019 | F41: =VLOOKUP(B41,データ!$B$3:$N$73,13,FALSE) -> pcs | G41: 300 | H41: =VLOOKUP(B41,データ!B10:D69,3,FALSE) -> 4.59 | J41: =H41*G41 -> 1377
A42: =A41+1 -> 10 | B42: LDBA053700-0 | D42: =VLOOKUP(B42,データ!$B$3:$N$77,2,FALSE) -> DOOR LOWER SASH L-S500H | E42: PHC-2025100019 | F42: =VLOOKUP(B42,データ!$B$3:$N$73,13,FALSE) -> pcs | G42: 300 | H42: =VLOOKUP(B42,データ!B11:D70,3,FALSE) -> 6.6 | J42: =H42*G42 -> 1980
A43: =A42+1 -> 11 | B43: LDBA053800-0 | D43: =VLOOKUP(B43,データ!$B$3:$N$77,2,FALSE) -> DOOR LOWER SASH R-S500H | E43: PHC-2025100019 | F43: =VLOOKUP(B43,データ!$B$3:$N$73,13,FALSE) -> pcs | G43: 300 | H43: =VLOOKUP(B43,データ!B12:D71,3,FALSE) -> 7.61 | J43: =H43*G43 -> 2283
A44: =A43+1 -> 12 | B44: LDBA061200-0 | D44: =VLOOKUP(B44,データ!$B$3:$N$77,2,FALSE) -> DOOR LOWER SASH L | E44: PHC-2025100063 PHC-2023060092 | F44: =VLOOKUP(B44,データ!$B$3:$N$73,13,FALSE) -> pcs | G44: 323 | H44: =VLOOKUP(B44,データ!B13:D72,3,FALSE) -> 13.28 | J44: =H44*G44 -> 4289.44
A45: =A44+1 -> 13 | B45: LDBA061300-0 | D45: =VLOOKUP(B45,データ!$B$3:$N$77,2,FALSE) -> DOOR LOWER SASH R | E45: PHC-2023060092 | F45: =VLOOKUP(B45,データ!$B$3:$N$73,13,FALSE) -> pcs | G45: 6 | H45: =VLOOKUP(B45,データ!B14:D73,3,FALSE) -> 12.36 | J45: =H45*G45 -> 74.16
... A47: =A46+1 -> 15 | B47: LDBA053500-0 | D47: =VLOOKUP(B47,データ!$B$3:$N$77,2,FALSE) -> LIGHT COVER-S500H | E47: PHC-2025100019 | F47: =VLOOKUP(B47,データ!$B$3:$N$73,13,FALSE) -> pcs | G47: 300 | H47: =VLOOKUP(B47,データ!B16:D75,3,FALSE) -> 2.81 | J47: =H47*G47 -> 843
A48: =A47+1 -> 16 | B48: LDBA060800-0 | D48: =VLOOKUP(B48,データ!$B$3:$N$77,2,FALSE) -> RAIL SIDE R | E48: PHC-2025100063 | F48: =VLOOKUP(B48,データ!$B$3:$N$73,13,FALSE) -> pcs | G48: 320 | H48: =VLOOKUP(B48,データ!B16:D75,3,FALSE) -> 10.48 | J48: =H48*G48 -> 3353.6
A49: =A48+1 -> 17 | B49: LDBA060501-1 | D49: =VLOOKUP(B49,データ!$B$3:$N$77,2,FALSE) -> RAIL TOP S1200H | E49: PHC-2024070112 | F49: =VLOOKUP(B49,データ!$B$3:$N$73,13,FALSE) -> pcs | G49: 80 | H49: =VLOOKUP(B49,データ!B17:D76,3,FALSE) -> 15.07 | J49: =H49*G49 -> 1205.6
A50: =A49+1 -> 18
A51: 合計 （Total) | J51: =SUM(J33:K50) -> 37141.31
A53: Terms: FOB HAI PHONG VIETNAM Incoterms® 2020 | H53: 署名（ Singnature )
A54: 原産国 (Country of Origin) : VIETNAM

Sheet PACKING LIST
A1: PACKING LIST
I5: =INVOICE!H5 -> インボイス作成日（Date): 24/11/2025
A8: 依頼住 (Shipper Address) | I8: =INVOICE!H7 -> Invoice No [Invoice No]
A10: MASUDA VINYL VIETNAM CO.,LTD
A11: LOT NO1 DONG VANG DINH TRAM INDUSTRIAL ZONE | I11: (原産国) Country of Origin | L11: (仕向先国名) Country of Destination
A12: NENH WARD BAC NINH PROVINCE
A13: TEL : 0204 3662 777 | I13: VIETNAM | L13: INDONESIA
A14: FAX : 0204 3662 825 | I14: 支払条件 (Terms of Payment)
I15: =INVOICE!H14 -> Invoice will be closed on delivery day and payment after 60days
A17: 荷受人(Consigneer)
A20: PT. Sumitronics Indonesia | I20: 備考 (Remark):
A21: =INVOICE!A19 -> KAWASAN INDUSTRIAL EJIP PLOT 1E-2 SUKARESMI CIKARANG SELATAN | I21: P | J21: 有償（Commerical Value)
A22: =INVOICE!A20 -> 0 | J22: 無償（No Commerical Value)
A23: TEL :62-21-8975220 ext : 252
J24: 贈物（Gift)
J25: 商品見本（ Sample, No Commercial Value )
A26: From (発地国) | J26: その他（Other)
A27: BACNINH VIETNAM
A28: To (着地国)
A29: =INVOICE!A27 -> JAKARTA INDONESIA
A31: =INVOICE!A29 -> 品番 ( Part No) | D31: =INVOICE!D29 -> 品名 (Part Name) | E31: 注文書No PO No | F31: 単位 （Unit） | G31: 数量 （Quantity) | H31: 梱包 （Packing） | J31: 箱数 ( Number of Boxs) | K31: パレット数 ( Number of Pallets) | L31: 正味重量 (Net weight) | M31: 総重量 (Gross weight)
A35: 1 | B35: =INVOICE!B33 -> LDBA043800-2 | D35: =INVOICE!D33 -> RAIL TOP | E35: =INVOICE!E33 -> PHC-2025100007 | F35: =INVOICE!F33 -> pcs | G35: =INVOICE!G33 -> 300 | H35: =VLOOKUP(B35,データ!B3:F77,5,FALSE) -> 40 | J35: =ROUNDUP(G35/H35,0) -> 8 | K35: 7 | L35: =G35*O35/1000 -> 0 | M35: =L35+J35*0.77+10 -> 16.16
A36: =A35+1 -> 2 | B36: =INVOICE!B34 -> LDBA043900-2 | D36: =INVOICE!D34 -> RAIL BOTTOM | E36: =INVOICE!E34 -> PHC-2025100007 | F36: =INVOICE!F34 -> pcs | G36: =INVOICE!G34 -> 300 | H36: =VLOOKUP(B36,データ!B4:F78,5,FALSE) -> 46 | J36: =ROUNDUP(G36/H36,0) -> 7 | L36: =G36*O36/1000 -> 0 | M36: =L36+J36*0.77+10 -> 15.39
A37: =A36+1 -> 3 | B37: =INVOICE!B35 -> LDBA044901-2 | D37: =INVOICE!D35 -> DOOR OUTER SASH R -S500 | E37: =INVOICE!E35 -> PHC-2025100019 | F37: =INVOICE!F35 -> pcs | G37: =INVOICE!G35 -> 329 | H37: =VLOOKUP(B37,データ!B5:F79,5,FALSE) -> 42 | J37: =ROUNDUP(G37/H37,0) -> 8 | L37: =G37*O37/1000 -> 0 | M37: =L37+J37*0.77+10 -> 16.16
A38: =A37+1 -> 4 | B38: =INVOICE!B36 -> LDBA045001-2 | D38: =INVOICE!D36 -> DOOR OUTER SASH L-S500 | E38: =INVOICE!E36 -> PHC-2025100019 | F38: =INVOICE!F36 -> pcs | G38: =INVOICE!G36 -> 331 | H38: =VLOOKUP(B38,データ!B6:F80,5,FALSE) -> 42 | J38: =ROUNDUP(G38/H38,0) -> 8 | L38: =G38*O38/1000 -> 0 | M38: =L38+J38*0.77+10 -> 16.16
A39: =A38+1 -> 5 | B39: =INVOICE!B37 -> LDBA045101-3 | D39: =INVOICE!D37 -> DOOR CENTER SASH-S500H | E39: =INVOICE!E37 -> PHC-2025100007 PHC-2025100019 | F39: =INVOICE!F37 -> pcs | G39: =INVOICE!G37 -> 640 | H39: =VLOOKUP(B39,データ!B7:F81,5,FALSE) -> 40 | J39: =ROUNDUP(G39/H39,0) -> 16 | L39: =G39*O39/1000 -> 0 | M39: =L39+J39*0.77+20 -> 32.32
A40: =A39+1 -> 6 | B40: =INVOICE!B38 -> LDBA053601-2 | D40: =INVOICE!D38 -> DOOR UPPER SASH L-S500H | E40: =INVOICE!E38 -> PHC-2025100019 | F40: =INVOICE!F38 -> pcs | G40: =INVOICE!G38 -> 300 | H40: =VLOOKUP(B40,データ!B8:F82,5,FALSE) -> 80 | J40: =ROUNDUP(G40/H40,0) -> 4 | L40: =G40*O40/1000 -> 0 | M40: =L40+J40*0.77+5 -> 8.08
A41: =A40+1 -> 7 | B41: =INVOICE!B39 -> LDBA064301-2 | D41: =INVOICE!D39 -> DOOR UPPER SASH R-S500H | E41: =INVOICE!E39 -> PHC-2025100007 | F41: =INVOICE!F39 -> pcs | G41: =INVOICE!G39 -> 300 | H41: =VLOOKUP(B41,データ!B9:F83,5,FALSE) -> 80 | J41: =ROUNDUP(G41/H41,0) -> 4 | L41: =G41*O41/1000 -> 0 | M41: =L41+J41*0.77+5 -> 8.08
A42: =A41+1 -> 8 | B42: =INVOICE!B40 -> LDBA053603-0 | D42: =INVOICE!D40 -> DOOR UPPER SASH L-S150H | E42: =INVOICE!E40 -> PHC-2025100019 | F42: =INVOICE!F40 -> pcs | G42: =INVOICE!G40 -> 300 | H42: =VLOOKUP(B42,データ!B10:F84,5,FALSE) -> 80 | J42: =ROUNDUP(G42/H42,0) -> 4 | L42: =G42*O42/1000 -> 0 | M42: =L42+J42*0.77+5 -> 8.08
A43: =A42+1 -> 9 | B43: =INVOICE!B41 -> LDBA064303-0 | D43: =INVOICE!D41 -> DOOR UPPER SASH R-S150H | E43: =INVOICE!E41 -> PHC-2025100019 | F43: =INVOICE!F41 -> pcs | G43: =INVOICE!G41 -> 300 | H43: =VLOOKUP(B43,データ!B11:F85,5,FALSE) -> 80 | J43: =ROUNDUP(G43/H43,0) -> 4 | L43: =G43*O43/1000 -> 0 | M43: =L43+J43*0.77+5 -> 8.08
A44: =A43+1 -> 10 | B44: =INVOICE!B42 -> LDBA053700-0 | D44: =INVOICE!D42 -> DOOR LOWER SASH L-S500H | E44: =INVOICE!E42 -> PHC-2025100019 | F44: =INVOICE!F42 -> pcs | G44: =INVOICE!G42 -> 300 | H44: =VLOOKUP(B44,データ!B12:F86,5,FALSE) -> 50 | J44: =ROUNDUP(G44/H44,0) -> 6 | L44: =G44*O44/1000 -> 0 | M44: =L44+J44*0.77+10 -> 14.62
A45: =A44+1 -> 11 | B45: =INVOICE!B43 -> LDBA053800-0 | D45: =INVOICE!D43 -> DOOR LOWER SASH R-S500H | E45: =INVOICE!E43 -> PHC-2025100019 | F45: =INVOICE!F43 -> pcs | G45: =INVOICE!G43 -> 300 | H45: =VLOOKUP(B45,データ!B13:F87,5,FALSE) -> 50 | J45: =ROUNDUP(G45/H45,0) -> 6 | L45: =G45*O45/1000 -> 0 | M45: =L45+J45*0.77+10 -> 14.62
A46: =A45+1 -> 12 | B46: =INVOICE!B44 -> LDBA061200-0 | D46: =INVOICE!D44 -> DOOR LOWER SASH L | E46: =INVOICE!E44 -> PHC-2025100063 PHC-2023060092 | F46: =INVOICE!F44 -> pcs | G46: =INVOICE!G44 -> 323 | H46: =VLOOKUP(B46,データ!B14:F88,5,FALSE) -> 20 | J46: =ROUNDUP(G46/H46,0) -> 17 | L46: =G46*O46/1000 -> 0 | M46: =L46+J46*0.77+20 -> 33.09
A47: =A46+1 -> 13 | B47: =INVOICE!B45 -> LDBA061300-0 | D47: =INVOICE!D45 -> DOOR LOWER SASH R | E47: =INVOICE!E45 -> PHC-2023060092 | F47: =INVOICE!F45 -> pcs | G47: =INVOICE!G45 -> 6 | H47: 6 | J47: =ROUNDUP(G47/H47,0) -> 1 | L47: =G47*O47/1000 -> 0 | M47: =L47+J47*0.77 -> 0.77
A48: =A47+1 -> 14 | B48: =INVOICE!B46 -> LDBA093301-0 | D48: =INVOICE!D46 -> DOOR CENTER SASH | E48: =INVOICE!E46 -> PHC-2024090117 | F48: =INVOICE!F46 -> pcs | G48: =INVOICE!G46 -> 13 | H48: 13 | J48: =ROUNDUP(G48/H48,0) -> 1 | L48: =G48*O48/1000 -> 0 | M48: =L48+J48*0.77 -> 0.77
A49: =A48+1 -> 15 | B49: =INVOICE!B47 -> LDBA053500-0 | D49: =INVOICE!D47 -> LIGHT COVER-S500H | E49: =INVOICE!E47 -> PHC-2025100019 | F49: =INVOICE!F47 -> pcs | G49: =INVOICE!G47 -> 300 | H49: =VLOOKUP(B49,データ!B17:F91,5,FALSE) -> 170 | J49: =ROUNDUP(G49/H49,0) -> 2 | L49: =G49*O49/1000 -> 0 | M49: =L49+J49*0.77+5 -> 6.54
A50: =A49+1 -> 16 | B50: =INVOICE!B48 -> LDBA060800-0 | D50: =INVOICE!D48 -> RAIL SIDE R | E50: =INVOICE!E48 -> PHC-2025100063 | F50: =INVOICE!F48 -> pcs | G50: =INVOICE!G48 -> 320 | H50: =VLOOKUP(B50,データ!B18:F92,5,FALSE) -> 34 | J50: =ROUNDUP(G50/H50,0) -> 10 | L50: =G50*O50/1000 -> 0 | M50: =L50+J50*0.77+10 -> 17.7
A51: =A50+1 -> 17 | B51: =INVOICE!B49 -> LDBA060501-1 | D51: =INVOICE!D49 -> RAIL TOP S1200H | E51: =INVOICE!E49 -> PHC-2024070112 | F51: =INVOICE!F49 -> pcs | G51: =INVOICE!G49 -> 80 | H51: =VLOOKUP(B51,データ!B19:F93,5,FALSE) -> 22 | J51: =ROUNDUP(G51/H51,0) -> 4 | L51: =G51*O51/1000 -> 0 | M51: =L51+J51*0.77+5 -> 8.08
A52: =A51+1 -> 18
A53: 合計 （Total) | G53: =SUM(G35:G52) -> 4742 | J53: =SUM(J35:J52) -> 110 | K53: =SUM(K35:K52) -> 7 | L53: =SUM(L35:L52) -> 0 | M53: =SUM(M35:M52) -> 224.7
...

Sheet IV tổng
A1: INVOICE
H5: =INVOICE!H5 -> インボイス作成日（Date): 24/11/2025
A7: 依頼住 (Shipper Address) | H7: =INVOICE!H7 -> Invoice No [Invoice No]
A9: MASUDA VINYL VIETNAM CO.,LTD
A10: LOT NO1 DONG VANG DINH TRAM INDUSTRIAL ZONE | H10: (原産国) Country of Origin | J10: (仕向先国名) Country of Destination
A11: NENH TOWN VIET YEN DISTRICT BAC GIANG PROVINCE
A12: TEL : 0204 3662 777 | H12: VIETNAM | J12: INDONESIA
A13: FAX : 0204 3662 825
H14: Invoice will be closed on delivery day and payment after 60days
A15: 荷受人(Consigneer)
A18: PT. Sumitronics Indonesia
A19: KAWASAN INDUSTRIAL EJIP PLOT 1E-2 SUKARESMI CIKARANG SELATAN | H19: 備考 (Remark):
A20: KAB. BEKASI JAWA BARAT 17530 INDONESIA
A21: TEL :62-21-8975220 ext : 252 | H21: 有償（Commerical Value)
H22: 無償（No Commerical Value)
A24: From (発地国) | H24: 贈物（Gift)
A25: BACGIANG VIETNAM | H25: 商品見本（ Sample, No Commercial Value )
A26: To (着地国) | H26: その他（Other)
A27: JAKARTA INDONESIA
A29: 品番 ( Part No) | D29: 品名 (Part Name) | E29: 注文書No PO No | F29: 単位 （Unit） | G29: 数量 （Quantity) | H29: 単価 （Unit Price） | J29: 合計 （Total Amount)
A33: 1 | B33: LDBA045101-3 | D33: =VLOOKUP(B33,データ!$B$3:$N$77,2,FALSE) -> DOOR CENTER SASH-S500H | F33: =VLOOKUP(B33,データ!$B$3:$N$37,13,FALSE) -> pcs | G33: 600 | H33: =VLOOKUP(B33,データ!B1:D42,3,FALSE) -> 7.94 | J33: =H33*G33 -> 4764
A34: 2 | B34: LDBA043800-2 | D34: =VLOOKUP(B34,データ!$B$3:$N$77,2,FALSE) -> RAIL TOP | F34: =VLOOKUP(B34,データ!$B$3:$N$37,13,FALSE) -> pcs | G34: 600 | H34: =VLOOKUP(B34,データ!B2:D43,3,FALSE) -> 6.55 | J34: =H34*G34 -> 3930
A35: 3 | B35: LDBA043900-1 | D35: =VLOOKUP(B35,データ!$B$3:$N$77,2,FALSE) -> RAIL BOTTOM | F35: =VLOOKUP(B35,データ!$B$3:$N$37,13,FALSE) -> pcs | G35: 600 | H35: =VLOOKUP(B35,データ!B1:D43,3,FALSE) -> 8.67 | J35: =H35*G35 -> 5202
A36: =A35+1 -> 4 | B36: LDBA044000-0 | D36: =VLOOKUP(B36,データ!$B$3:$N$77,2,FALSE) -> RAIL SIDE | F36: =VLOOKUP(B36,データ!$B$3:$N$37,13,FALSE) -> pcs | G36: 600 | H36: =VLOOKUP(B36,データ!B1:D44,3,FALSE) -> 4.27 | J36: =H36*G36 -> 2562
A37: =A36+1 -> 5 | B37: LDBA044100-0 | D37: =VLOOKUP(B37,データ!$B$3:$N$77,2,FALSE) -> RAIL SIDE | F37: =VLOOKUP(B37,データ!$B$3:$N$37,13,FALSE) -> pcs | G37: 1200 | H37: =VLOOKUP(B37,データ!B1:D45,3,FALSE) -> 7.8 | J37: =H37*G37 -> 9360
A38: =A37+1 -> 6 | B38: LDBA044400-3 | D38: =VLOOKUP(B38,データ!$B$3:$N$77,2,FALSE) -> DOOR LOWER SASH R | F38: =VLOOKUP(B38,データ!$B$3:$N$37,13,FALSE) -> pcs | G38: 600 | H38: =VLOOKUP(B38,データ!B1:D46,3,FALSE) -> 6.22 | J38: =H38*G38 -> 3732
A39: =A38+1 -> 7 | B39: LDBA044500-3 | D39: =VLOOKUP(B39,データ!$B$3:$N$77,2,FALSE) -> DOOR LOWER SASH L | F39: =VLOOKUP(B39,データ!$B$3:$N$37,13,FALSE) -> pcs | G39: 600 | H39: =VLOOKUP(B39,データ!B2:D47,3,FALSE) -> 5.84 | J39: =H39*G39 -> 3504
A40: =A39+1 -> 8 | B40: LDBA045100-8 | D40: =VLOOKUP(B40,データ!$B$3:$N$77,2,FALSE) -> #N/A | F40: =VLOOKUP(B40,データ!$B$3:$N$37,13,FALSE) -> #N/A | G40: 320 | H40: =VLOOKUP(B40,データ!B2:D47,3,FALSE) -> #N/A | J40: =H40*G40 -> #N/A
A41: =A40+1 -> 9 | B41: LDBA053500-0 | D41: =VLOOKUP(B41,データ!$B$3:$N$77,2,FALSE) -> LIGHT COVER-S500H | F41: =VLOOKUP(B41,データ!$B$3:$N$37,13,FALSE) -> pcs | G41: 300 | H41: =VLOOKUP(B41,データ!B3:D48,3,FALSE) -> 2.81 | J41: =H41*G41 -> 843
A42: =A41+1 -> 10 | B42: LDBA053603-0 | D42: =VLOOKUP(B42,データ!$B$3:$N$77,2,FALSE) -> DOOR UPPER SASH L-S150H | F42: =VLOOKUP(B42,データ!$B$3:$N$37,13,FALSE) -> pcs | G42: 600 | H42: =VLOOKUP(B42,データ!B3:D48,3,FALSE) -> 4.59 | J42: =H42*G42 -> 2754
A43: =A42+1 -> 11 | B43: LDBA053900-1 | D43: =VLOOKUP(B43,データ!$B$3:$N$77,2,FALSE) -> RAIL TOP-S500H | F43: =VLOOKUP(B43,データ!$B$3:$N$37,13,FALSE) -> pcs | G43: 300 | H43: =VLOOKUP(B43,データ!B6:D50,3,FALSE) -> 6.13 | J43: =H43*G43 -> 1839
A44: =A43+1 -> 12 | B44: LDBA054000-2 | D44: =VLOOKUP(B44,データ!$B$3:$N$77,2,FALSE) -> RAIL BOTTOM-S500H | F44: =VLOOKUP(B44,データ!$B$3:$N$37,13,FALSE) -> pcs | G44: 300 | H44: =VLOOKUP(B44,データ!B7:D51,3,FALSE) -> 9.87 | J44: =H44*G44 -> 2961
A45: =A44+1 -> 13 | B45: LDBA064303-0 | D45: =VLOOKUP(B45,データ!$B$3:$N$77,2,FALSE) -> DOOR UPPER SASH R-S150H | F45: =VLOOKUP(B45,データ!$B$3:$N$37,13,FALSE) -> pcs | G45: 600 | H45: =VLOOKUP(B45,データ!B8:D52,3,FALSE) -> 4.59 | J45: =H45*G45 -> 2754
A46: =A45+1 -> 14
A54: 合計 （Total) | J54: =SUM(J33:K53) -> #N/A
A56: Terms: FOB HAI PHONG VIETNAM Incoterms® 2020 | H56: 署名（ Singnature )
A57: 原産国 (Country of Origin) : VIETNAM

Sheet PL tổng
A1: PACKING LIST
I5: ='PACKING LIST'!I5:M5 -> インボイス作成日（Date): 24/11/2025
A8: 依頼住 (Shipper Address) | I8: Invoice No MVV-002-2023
A10: MASUDA VINYL VIETNAM CO.,LTD
A11: LOT NO1 DONG VANG DINH TRAM INDUSTRIAL ZONE | I11: (原産国) Country of Origin | L11: (仕向先国名) Country of Destination
A12: NENH TOWN VIET YEN DISTRICT BAC GIANG PROVINCE
A13: TEL : 0204 3662 777 | I13: VIETNAM | L13: INDONESIA
A14: FAX : 0204 3662 825 | I14: 支払条件 (Terms of Payment)
I15: =INVOICE!H14 -> Invoice will be closed on delivery day and payment after 60days
A17: 荷受人(Consigneer)
A20: PT. Sumitronics Indonesia | I20: 備考 (Remark):
A21: =INVOICE!A19 -> KAWASAN INDUSTRIAL EJIP PLOT 1E-2 SUKARESMI CIKARANG SELATAN
A22: =INVOICE!A20 -> 0 | I22: 有償（Commerical Value)
A23: TEL :62-21-8975220 ext : 252 | I23: 無償（No Commerical Value)
I25: 贈物（Gift)
A26: From (発地国) | I26: 商品見本（ Sample, No Commercial Value )
A27: BACGIANG VIETNAM | I27: その他（Other)
A28: To (着地国)
A29: =INVOICE!A27 -> JAKARTA INDONESIA
A31: =INVOICE!A29 -> 品番 ( Part No) | D31: =INVOICE!D29 -> 品名 (Part Name) | E31: 注文書No PO No | F31: 単位 （Unit） | G31: 数量 （Quantity) | H31: 梱包 （Packing） | J31: 箱数 ( Number of Boxs) | K31: パレット数 ( Number of Pallets) | L31: 正味重量 (Net weight) | M31: 総重量 (Gross weight)
A35: 1 | B35: ='IV tổng'!B33 -> LDBA045101-3 | D35: ='IV tổng'!D33 -> DOOR CENTER SASH-S500H | F35: ='IV tổng'!F33 -> pcs | G35: ='IV tổng'!G33 -> 600 | H35: =VLOOKUP(B35,データ!B3:F39,5,FALSE) -> 40 | J35: 4 | L35: =G35*O35/1000 -> 248.4 | M35: =L35+J35*0.77+20 -> 271.48 | O35: =VLOOKUP(B35,データ!B1:L40,4,FALSE) -> 414 | P35: =J35*0.9 -> 3.6
A36: =A35+1 -> 2 | B36: ='IV tổng'!B34 -> LDBA043800-2 | D36: ='IV tổng'!D34 -> RAIL TOP | F36: ='IV tổng'!F34 -> pcs | G36: ='IV tổng'!G34 -> 600 | H36: =VLOOKUP(B36,データ!B1:F40,5,FALSE) -> 40 | J36: =G36/H36 -> 15 | L36: =G36*O36/1000 -> 247.2 | M36: =L36+J36*0.77+10 -> 268.75 | O36: =VLOOKUP(B36,データ!B2:L41,4,FALSE) -> 412 | P36: =J36*0.9 -> 13.5
A37: =A36+1 -> 3 | B37: ='IV tổng'!B35 -> LDBA043900-1 | D37: ='IV tổng'!D35 -> RAIL BOTTOM | F37: ='IV tổng'!F35 -> pcs | G37: ='IV tổng'!G35 -> 600 | H37: =VLOOKUP(B37,データ!B1:F41,5,FALSE) -> 46 | J37: 14 | L37: =G37*O37/1000 -> 247.2 | M37: =L37+J37*0.77+10 -> 267.98 | O37: =VLOOKUP(B37,データ!B3:L42,4,FALSE) -> 412 | P37: =J37*0.9 -> 12.6
A38: =A37+1 -> 4 | B38: ='IV tổng'!B36 -> LDBA044000-0 | D38: ='IV tổng'!D36 -> RAIL SIDE | F38: ='IV tổng'!F36 -> pcs | G38: ='IV tổng'!G36 -> 600 | H38: =VLOOKUP(B38,データ!B2:F42,5,FALSE) -> 68 | J38: 9 | L38: =G38*O38/1000 -> 216 | M38: =L38+J38*0.77 -> 222.93 | O38: =VLOOKUP(B38,データ!B5:L43,4,FALSE) -> 360 | P38: =J38*0.9 -> 8.1
A39: =A38+1 -> 5 | B39: ='IV tổng'!B37 -> LDBA044100-0 | D39: ='IV tổng'!D37 -> RAIL SIDE | F39: ='IV tổng'!F37 -> pcs | G39: ='IV tổng'!G37 -> 1200 | H39: =VLOOKUP(B39,データ!B3:F43,5,FALSE) -> 34 | J39: 36 | L39: =G39*O39/1000 -> 847.2 | M39: =L39+J39*0.77 -> 874.92 | O39: =VLOOKUP(B39,データ!B6:L44,4,FALSE) -> 706 | P39: =J39*0.9 -> 32.4
A40: =A39+1 -> 6 | B40: ='IV tổng'!B38 -> LDBA044400-3 | D40: ='IV tổng'!D38 -> DOOR LOWER SASH R | F40: ='IV tổng'!F38 -> pcs | G40: ='IV tổng'!G38 -> 600 | H40: =VLOOKUP(B40,データ!B6:F45,5,FALSE) -> 26 | J40: 24 | L40: =G40*O40/1000 -> 127.2 | M40: =L40+J40*0.77 -> 145.68 | O40: =VLOOKUP(B40,データ!B1:L46,4,FALSE) -> 212 | P40: =J40*0.9 -> 21.6
A41: =A40+1 -> 7 | B41: ='IV tổng'!B39 -> LDBA044500-3 | D41: ='IV tổng'!D39 -> DOOR LOWER SASH L | F41: ='IV tổng'!F39 -> pcs | G41: ='IV tổng'!G39 -> 600 | H41: =VLOOKUP(B41,データ!B7:F46,5,FALSE) -> 26 | J41: 24 | L41: =G41*O41/1000 -> 127.2 | M41: =L41+J41*0.77+20 -> 165.68 | O41: =VLOOKUP(B41,データ!B9:L47,4,FALSE) -> 212 | P41: =J41*0.9 -> 21.6
A42: =A41+1 -> 8 | B42: ='IV tổng'!B40 -> LDBA045100-8 | D42: ='IV tổng'!D40 -> #N/A | F42: ='IV tổng'!F40 -> #N/A | G42: ='IV tổng'!G40 -> 320 | H42: =VLOOKUP(B42,データ!B8:F47,5,FALSE) -> #N/A | J42: =G42/H42 -> #N/A | L42: =G42*O42/1000 -> #N/A | M42: =L42+J42*0.77 -> #N/A | O42: =VLOOKUP(B42,データ!B10:L48,4,FALSE) -> #N/A | P42: =J42*0.9 -> #N/A
A43: =A42+1 -> 9 | B43: ='IV tổng'!B41 -> LDBA053500-0 | D43: ='IV tổng'!D41 -> LIGHT COVER-S500H | F43: ='IV tổng'!F41 -> pcs | G43: ='IV tổng'!G41 -> 300 | H43: =VLOOKUP(B43,データ!B9:F48,5,FALSE) -> 170 | J43: 2 | L43: =G43*O43/1000 -> 27 | M43: =L43+J43*0.77+20 -> 48.54 | O43: =VLOOKUP(B43,データ!B11:L49,4,FALSE) -> 90 | P43: =J43*0.9 -> 1.8
A44: =A43+1 -> 10 | B44: ='IV tổng'!B42 -> LDBA053603-0 | D44: ='IV tổng'!D42 -> DOOR UPPER SASH L-S150H | F44: ='IV tổng'!F42 -> pcs | G44: ='IV tổng'!G42 -> 600 | H44: =VLOOKUP(B44,データ!B10:F49,5,FALSE) -> 80 | J44: 8 | L44: =G44*O44/1000 -> 139.8 | M44: =L44+J44*0.77+20 -> 165.96 | O44: =VLOOKUP(B44,データ!B11:L50,4,FALSE) -> 233 | P44: =J44*0.9 -> 7.2
A45: =A44+1 -> 11 | B45: ='IV tổng'!B43 -> LDBA053900-1 | D45: ='IV tổng'!D43 -> RAIL TOP-S500H | F45: ='IV tổng'!F43 -> pcs | G45: ='IV tổng'!G43 -> 300 | H45: =VLOOKUP(B45,データ!B11:F51,5,FALSE) -> 40 | J45: 8 | L45: =G45*O45/1000 -> 104.4 | M45: =L45+J45*0.77+20 -> 130.56 | O45: =VLOOKUP(B45,データ!B12:L52,4,FALSE) -> 348 | P45: =J45*0.9 -> 7.2
A46: =A45+1 -> 12 | B46: ='IV tổng'!B44 -> LDBA054000-2 | D46: ='IV tổng'!D44 -> RAIL BOTTOM-S500H | F46: ='IV tổng'!F44 -> pcs | G46: ='IV tổng'!G44 -> 300 | H46: =VLOOKUP(B46,データ!B1:F52,5,FALSE) -> 46 | J46: 7 | L46: =G46*O46/1000 -> 163.5 | M46: =L46+J46*0.77+20 -> 188.89 | O46: =VLOOKUP(B46,データ!B1:L53,4,FALSE) -> 545 | P46: =J46*0.9 -> 6.3
A47: =A46+1 -> 13 | B47: ='IV tổng'!B45 -> LDBA064303-0 | D47: ='IV tổng'!D45 -> DOOR UPPER SASH R-S150H | F47: ='IV tổng'!F45 -> pcs | G47: ='IV tổng'!G45 -> 600 | H47: =VLOOKUP(B47,データ!B2:F53,5,FALSE) -> 80 | J47: 8 | L47: =G47*O47/1000 -> 139.8 | M47: =L47+J47*0.77+20 -> 165.96 | O47: =VLOOKUP(B47,データ!B2:L54,4,FALSE) -> 233 | P47: =J47*0.9 -> 7.2
A48: 合計 （Total) | G48: =SUM(G35:G47) -> 7220 | J48: =SUM(J35:J47) -> #N/A | K48: =SUM(K35:K47) -> 0 | L48: =SUM(L35:L47) -> #N/A | M48: =SUM(M35:M47) -> #N/A | N48: =SUM(N35:N47) -> 0
A50: =INVOICE!A54 -> 原産国 (Country of Origin) : VIETNAM
A51: 郵便物の個数 ( Number of pieces) : | D51: =G48 -> 7220
A52: 総重量（Gross weight) Kg : | D52: =M48 -> #N/A | I52: 署名（ Singnature )
A53: 原産国（Country of Origin) :VIETNAM | E53: =1.1*1.1*1.33+1.1*1.5*1.14*4 -> 9.1333
A54: 輸送方法 ( Shipped per) : SEA

Sheet IV tong
A1: INVOICE
H5: インボイス作成日（Date): 22/08/2021
A8: 依頼住 (Shipper Address) | H8: Invoice No MVV-029
A10: MASUDA VINYL VIETNAM CO.,LTD
A11: LOT NO1 DONG VANG DINH TRAM INDUSTRIAL ZONE | H11: (原産国) Country of Origin | J11: (仕向先国名) Country of Destination
A12: NENH TOWN VIET YEN DISTRICT BAC GIANG PROVINCE
A13: TEL : 0204 3662 777 | H13: VIETNAM | J13: INDONESIA
A14: FAX : 0204 3662 825 | H14: 支払条件 (Terms of Payment)
H15: Invoice will be closed on delivery day and payment after 60days
A16: 荷受人(Consigneer)
A19: PT. Sumitronics Indonesia
A20: KAWASAN INDUSTRIAL EJIP PLOT 1E-2 SUKARESMI CIKARANG SELATAN | H20: 備考 (Remark):
A21: KAB. BEKASI JAWA BARAT 17530 INDONESIA
A22: TEL :62-21-8975220 ext : 252 | H22: 有償（Commerical Value)
H23: 無償（No Commerical Value)
A25: From (発地国) | H25: 贈物（Gift)
A26: BACGIANG VIETNAM | H26: 商品見本（ Sample, No Commercial Value )
A27: To (着地国) | H27: その他（Other)
A28: JAKARTA INDONESIA
A30: 品番 ( Part No) | D30: 品名 (Part Name) | E30: 注文書No PO No | F30: 単位 （Unit） | G30: 数量 （Quantity) | H30: 単価 （Unit Price） | J30: 合計 （Total Amount)
A34: 1 | B34: LDBA053500-0 | D34: =VLOOKUP(B34,データ!$B$3:$N$27,2,FALSE) -> LIGHT COVER-S500H | F34: =VLOOKUP(B34,データ!$B$3:$N$37,13,FALSE) -> pcs | G34: 300 | H34: =VLOOKUP(B34,データ!$B$3:$D$37,3,FALSE) -> 2.81 | J34: =H34*G34 -> 843
A35: =A34+1 -> 2 | B35: LDBA053601-1 | D35: =VLOOKUP(B35,データ!$B$3:$N$27,2,FALSE) -> DOOR UPPER SASH L-S500H | F35: =VLOOKUP(B35,データ!$B$3:$N$37,13,FALSE) -> pcs | G35: 300 | H35: =VLOOKUP(B35,データ!$B$3:$D$37,3,FALSE) -> 4.79 | J35: =H35*G35 -> 1437
A36: =A35+1 -> 3 | B36: LDBA053700-0 | D36: =VLOOKUP(B36,データ!$B$3:$N$128,2,FALSE) -> DOOR LOWER SASH L-S500H | F36: =VLOOKUP(B36,データ!$B$3:$N$37,13,FALSE) -> pcs | G36: 300 | H36: =VLOOKUP(B36,データ!$B$3:$D$37,3,FALSE) -> 6.6 | J36: =H36*G36 -> 1980
A37: =A36+1 -> 4 | B37: LDBA053800-0 | D37: =VLOOKUP(B37,データ!$B$3:$N$128,2,FALSE) -> DOOR LOWER SASH R-S500H | F37: =VLOOKUP(B37,データ!$B$3:$N$37,13,FALSE) -> pcs | G37: 300 | H37: =VLOOKUP(B37,データ!$B$3:$D$37,3,FALSE) -> 7.61 | J37: =H37*G37 -> 2283
A38: =A37+1 -> 5 | B38: LDBA053900-1 | D38: =VLOOKUP(B38,データ!$B$3:$N$128,2,FALSE) -> RAIL TOP-S500H | F38: =VLOOKUP(B38,データ!$B$3:$N$37,13,FALSE) -> pcs | G38: 300 | H38: =VLOOKUP(B38,データ!$B$3:$D$37,3,FALSE) -> 6.13 | J38: =H38*G38 -> 1839
A39: =A38+1 -> 6 | B39: LDBA054000-2 | D39: =VLOOKUP(B39,データ!$B$3:$N$128,2,FALSE) -> RAIL BOTTOM-S500H | F39: =VLOOKUP(B39,データ!$B$3:$N$37,13,FALSE) -> pcs | G39: 300 | H39: =VLOOKUP(B39,データ!$B$3:$D$37,3,FALSE) -> 9.87 | J39: =H39*G39 -> 2961
B40: LDBA064301-1 | D40: =VLOOKUP(B40,データ!$B$3:$N$128,2,FALSE) -> DOOR UPPER SASH R-S500H | F40: =VLOOKUP(B40,データ!$B$3:$N$37,13,FALSE) -> pcs | G40: 300 | H40: =VLOOKUP(B40,データ!$B$3:$D$37,3,FALSE) -> 4.79 | J40: =H40*G40 -> 1437
B41: LDBA044901-0 | D41: =VLOOKUP(B41,データ!$B$3:$N$128,2,FALSE) -> #N/A | F41: =VLOOKUP(B41,データ!$B$3:$N$37,13,FALSE) -> #N/A | G41: 844 | H41: =VLOOKUP(B41,データ!$B$3:$D$37,3,FALSE) -> #N/A | J41: =H41*G41 -> #N/A
B42: LDBA045001-0 | D42: =VLOOKUP(B42,データ!$B$3:$N$128,2,FALSE) -> #N/A | F42: =VLOOKUP(B42,データ!$B$3:$N$37,13,FALSE) -> #N/A | G42: 623 | H42: =VLOOKUP(B42,データ!$B$3:$D$37,3,FALSE) -> #N/A | J42: =H42*G42 -> #N/A
B43: LDBA045100-7 | D43: =VLOOKUP(B43,データ!$B$3:$N$128,2,FALSE) -> DOOR CENTER SASH | F43: =VLOOKUP(B43,データ!$B$3:$N$37,13,FALSE) -> pcs | G43: 782 | H43: =VLOOKUP(B43,データ!$B$3:$D$37,3,FALSE) -> 7.94 | J43: =H43*G43 -> 6209.08
B44: LDBA044200-3 | D44: =VLOOKUP(B44,データ!$B$3:$N$128,2,FALSE) -> DOOR UPPER SASH | F44: =VLOOKUP(B44,データ!$B$3:$N$37,13,FALSE) -> pcs | G44: 2400 | H44: =VLOOKUP(B44,データ!$B$3:$D$37,3,FALSE) -> 4.19 | J44: =H44*G44 -> 10056
B45: LDBA044400-3 | D45: =VLOOKUP(B45,データ!$B$3:$N$128,2,FALSE) -> DOOR LOWER SASH R | F45: =VLOOKUP(B45,データ!$B$3:$N$37,13,FALSE) -> pcs | G45: 600 | H45: =VLOOKUP(B45,データ!$B$3:$D$37,3,FALSE) -> 6.22 | J45: =H45*G45 -> 3732
B46: LDBA044500-3 | D46: =VLOOKUP(B46,データ!$B$3:$N$128,2,FALSE) -> DOOR LOWER SASH L | F46: =VLOOKUP(B46,データ!$B$3:$N$37,13,FALSE) -> pcs | G46: 600 | H46: =VLOOKUP(B46,データ!$B$3:$D$37,3,FALSE) -> 5.84 | J46: =H46*G46 -> 3504
B47: LDBA044600-4 | D47: =VLOOKUP(B47,データ!$B$3:$N$128,2,FALSE) -> #N/A | F47: =VLOOKUP(B47,データ!$B$3:$N$37,13,FALSE) -> #N/A | G47: 459 | H47: =VLOOKUP(B47,データ!$B$3:$D$37,3,FALSE) -> #N/A | J47: =H47*G47 -> #N/A
A48: =A39+1 -> 7 | B48: LDBA044700-5 | D48: =VLOOKUP(B48,データ!$B$3:$N$128,2,FALSE) -> #N/A | F48: =VLOOKUP(B48,データ!$B$3:$N$37,13,FALSE) -> #N/A | G48: 439 | H48: =VLOOKUP(B48,データ!$B$3:$D$37,3,FALSE) -> #N/A | J48: =H48*G48 -> #N/A
A49: =A48+1 -> 8 | B49: LDBA044800-7 | D49: =VLOOKUP(B49,データ!$B$3:$N$128,2,FALSE) -> DOOR CENTER SASH | F49: =VLOOKUP(B49,データ!$B$3:$N$37,13,FALSE) -> pcs | G49: 554 | H49: =VLOOKUP(B49,データ!$B$3:$D$37,3,FALSE) -> 4.27 | J49: =H49*G49 -> 2365.58
B50: LDBA044000-0 | D50: =VLOOKUP(B50,データ!$B$3:$N$128,2,FALSE) -> RAIL SIDE | F50: =VLOOKUP(B50,データ!$B$3:$N$37,13,FALSE) -> pcs | G50: 600 | H50: =VLOOKUP(B50,データ!$B$3:$D$37,3,FALSE) -> 4.27 | J50: =H50*G50 -> 2562
B51: LDBA044100-0 | D51: =VLOOKUP(B51,データ!$B$3:$N$128,2,FALSE) -> RAIL SIDE | F51: =VLOOKUP(B51,データ!$B$3:$N$37,13,FALSE) -> pcs | G51: 600 | H51: =VLOOKUP(B51,データ!$B$3:$D$37,3,FALSE) -> 7.8 | J51: =H51*G51 -> 4680
A52: =A49+1 -> 9
A53: 合計 （Total) | J53: =SUM(J34:K52) -> #N/A
...

Sheet Dia chi
A3: MASUDA VINYL VET NAM
A4: LOT NO1 DONG VANG DINH TRAM INDUSTRIAL ZONE
A5: NENH WARD BAC NINH PROVINCE
A6: TEL : 0204 3662 777
A13: PT. SUMITRONICS INDONESIA
A14: KAWASAN INDUSTRIAL EJIP PLOT 1E-2 SUKARESMI CIKARANG SELATAN
A15: KAB. BEKASI JAWA BARAT 17857 INDONESIA
A16: TEL :62-21-8975220 ext : 252

Sheet Sheet1
A6: ① LDBA044100:24BOX | K6: ② LDBA045100 : 24BOX | T6: ⑤ LDBA044900 : 15BOX LDBA044100 : 9BOX | AE6: ⑧ LDBA044200 : 24BOX LDBA044400: 12BOX
A56: ③ LDBA043800 : 15BOX | K56: ④ LDBA043900 : 13BOX | U56: ⑥ LDBA044100 : 3BOX LDBA045100 : 6BOX LDBA045000 : 15BOX | AE56: ⑦ LDBA044400 : 11BOX LDBA044500 : 23BOX

Sheet Sheet2

Sheet データ
A2: No | B2: 品名 | D2: 単価 | E2: 重さ | F2: 梱包 | G2: 出荷数 | H2: 箱数 | I2: 使用材 | J2: 袋 | K2: 段ボール | L2: 総数量 | M2: Số lượng tối đa 1palet | N2: 単位 | O2: KT
A3: 1 | B3: LDBA043800-2 | C3: RAIL TOP | D3: 6.55 | E3: 412 | F3: 40 | G3: =_xlfn.IFNA(VLOOKUP(データ!B3,INVOICE!$B$33:$K$50,6,FALSE),0) -> 300 | H3: =ROUNDUP(G3/F3,0) -> 8 | I3: =G3*E3/1000 -> 123.6 | K3: =H3*0.7 -> 5.6 | L3: =K3+J3+I3 -> 129.2 | M3: 18 | N3: pcs | O3: 78mm x 25mmx710mm
A4: 2 | B4: LDBA043900-1 | C4: RAIL BOTTOM | D4: 8.67 | E4: 412 | F4: 46 | G4: =_xlfn.IFNA(VLOOKUP(データ!B4,INVOICE!$B$33:$K$50,6,FALSE),0) -> 0 | H4: =ROUNDUP(G4/F4,0) -> 0 | I4: =G4*E4/1000 -> 0 | K4: =H4*0.7 -> 0 | L4: =K4+J4+I4 -> 0 | M4: 18 | N4: pcs | O4: 33mm x 81mm x 749mm
A5: 3 | B5: LDBA043900-2 | C5: RAIL BOTTOM | D5: 9.88 | E5: 412 | F5: 46 | G5: =_xlfn.IFNA(VLOOKUP(データ!B5,INVOICE!$B$33:$K$50,6,FALSE),0) -> 300 | H5: =ROUNDUP(G5/F5,0) -> 7 | I5: =G5*E5/1000 -> 123.6 | K5: =H5*0.7 -> 4.9 | L5: =K5+J5+I5 -> 128.5 | M5: 18 | N5: pcs | O5: 33mm x 81mm x 749mm
A6: =A5+1 -> 4 | B6: LDBA044000-0 | C6: RAIL SIDE | D6: 4.27 | E6: 360 | F6: 68 | G6: =_xlfn.IFNA(VLOOKUP(データ!B6,INVOICE!$B$33:$K$50,6,FALSE),0) -> 0 | H6: =ROUNDUP(G6/F6,0) -> 0 | I6: =G6*E6/1000 -> 0 | K6: =H6*0.7 -> 0 | L6: =K6+J6+I6 -> 0 | M6: 18 | N6: pcs | O6: 15mm x 78mm x 727mm
A7: =A6+1 -> 5 | B7: LDBA044100-0 | C7: RAIL SIDE | D7: 7.8 | E7: 706 | F7: 34 | G7: =_xlfn.IFNA(VLOOKUP(データ!B7,INVOICE!$B$33:$K$50,6,FALSE),0) -> 0 | H7: =ROUNDUP(G7/F7,0) -> 0 | I7: =G7*E7/1000 -> 0 | K7: =H7*0.7 -> 0 | L7: =K7+J7+I7 -> 0 | M7: 24 | N7: pcs | O7: 15mm x 78mm x 1724mm
A8: =A7+1 -> 6 | B8: LDBA044200-3 | C8: DOOR UPPER SASH | D8: 4.19 | E8: 156 | F8: 80 | G8: =_xlfn.IFNA(VLOOKUP(データ!B8,INVOICE!$B$33:$K$50,6,FALSE),0) -> 0 | H8: =ROUNDUP(G8/F8,0) -> 0 | I8: =G8*E8/1000 -> 0 | K8: =H8*0.7 -> 0 | L8: =K8+J8+I8 -> 0 | M8: 32 | N8: pcs
A9: =A8+1 -> 7 | B9: LDBA044400-3 | C9: DOOR LOWER SASH R | D9: 6.22 | E9: 212 | F9: 26 | G9: =_xlfn.IFNA(VLOOKUP(データ!B9,INVOICE!$B$33:$K$50,6,FALSE),0) -> 0 | H9: =ROUNDUP(G9/F9,0) -> 0 | I9: =G9*E9/1000 -> 0 | K9: =H9*0.7 -> 0 | L9: =K9+J9+I9 -> 0 | M9: 32 | N9: pcs | O9: 28mm x 70mm x 353mm
A10: =A9+1 -> 8 | B10: LDBA044500-3 | C10: DOOR LOWER SASH L | D10: 5.84 | E10: 212 | F10: 26 | G10: =_xlfn.IFNA(VLOOKUP(データ!B10,INVOICE!$B$33:$K$50,6,FALSE),0) -> 0 | H10: =ROUNDUP(G10/F10,0) -> 0 | I10: =G10*E10/1000 -> 0 | K10: =H10*0.7 -> 0 | L10: =K10+J10+I10 -> 0 | M10: 32 | N10: pcs | O10: 28mm x 70mm x 353mm
B11: LDBA044600-6 | C11: DOOR OUTER SASH R | D11: 6.84 | E11: 250 | F11: 60 | G11: =_xlfn.IFNA(VLOOKUP(データ!B11,INVOICE!$B$33:$K$50,6,FALSE),0) -> 0 | H11: =ROUNDUP(G11/F11,0) -> 0 | I11: =G11*E11/1000 -> 0 | K11: =H11*0.7 -> 0 | L11: =K11+J11+I11 -> 0 | M11: 19 | N11: pcs
B12: LDBA044700-7 | C12: DOOR OUTER SASH L | D12: 6.84 | E12: 250 | F12: 60 | G12: =_xlfn.IFNA(VLOOKUP(データ!B12,INVOICE!$B$33:$K$50,6,FALSE),0) -> 0 | H12: =ROUNDUP(G12/F12,0) -> 0 | I12: =G12*E12/1000 -> 0 | K12: =H12*0.7 -> 0 | L12: =K12+J12+I12 -> 0 | M12: 21 | N12: pcs
A13: =#REF!+1 -> #REF! | B13: LDBA044800-7 | C13: DOOR CENTER SASH | D13: 4.27 | E13: 220 | F13: 70 | G13: =_xlfn.IFNA(VLOOKUP(データ!B13,INVOICE!$B$33:$K$50,6,FALSE),0) -> 0 | H13: =ROUNDUP(G13/F13,0) -> 0 | I13: =G13*E13/1000 -> 0 | K13: =H13*0.7 -> 0 | L13: =K13+J13+I13 -> 0 | M13: 18 | N13: pcs
B14: LDBA044800-8 | C14: DOOR CENTER SASH | D14: 4.27 | E14: 220 | F14: 70 | G14: =_xlfn.IFNA(VLOOKUP(データ!B14,INVOICE!$B$33:$K$50,6,FALSE),0) -> 0 | H14: =ROUNDUP(G14/F14,0) -> 0 | I14: =G14*E14/1000 -> 0 | K14: =H14*0.7 -> 0 | L14: =K14+J14+I14 -> 0 | M14: 19 | N14: pcs
B15: LDBA044800-9 | C15: DOOR CENTER SASH | D15: 4.27 | E15: 220 | F15: 70 | G15: =_xlfn.IFNA(VLOOKUP(データ!B15,INVOICE!$B$33:$K$50,6,FALSE),0) -> 0 | H15: =ROUNDUP(G15/F15,0) -> 0 | I15: =G15*E15/1000 -> 0 | K15: =H15*0.7 -> 0 | L15: =K15+J15+I15 -> 0 | M15: 19 | N15: pcs
B16: LDBA093301-0 | C16: DOOR CENTER SASH | D16: 4.27 | E16: 220 | F16: 80 | G16: =_xlfn.IFNA(VLOOKUP(データ!B16,INVOICE!$B$33:$K$50,6,FALSE),0) -> 13 | H16: =ROUNDUP(G16/F16,0) -> 1 | I16: =G16*E16/1000 -> 2.86 | K16: =H16*0.7 -> 0.7 | L16: =K16+J16+I16 -> 3.56 | M16: 19 | N16: pcs
A17: =A13+1 -> #REF! | B17: LDBA045100-7 | C17: DOOR CENTER SASH | D17: 7.94 | E17: 410 | F17: 40 | G17: =_xlfn.IFNA(VLOOKUP(データ!B17,INVOICE!$B$33:$K$50,6,FALSE),0) -> 0 | H17: =ROUNDUP(G17/F17,0) -> 0 | I17: =G17*E17/1000 -> 0 | K17: =H17*0.7 -> 0 | L17: =K17+J17+I17 -> 0 | M17: 24 | N17: pcs
B18: LDBA045100-9 | C18: DOOR CENTER SASH | D18: 7.94 | E18: 410 | F18: 40 | G18: =_xlfn.IFNA(VLOOKUP(データ!B18,INVOICE!$B$33:$K$50,6,FALSE),0) -> 0 | H18: =ROUNDUP(G18/F18,0) -> 0 | I18: =G18*E18/1000 -> 0 | K18: =H18*0.7 -> 0 | L18: =K18+J18+I18 -> 0 | M18: 25 | N18: pcs
A19: =A17+1 -> #REF! | B19: LDBA043601-0 | C19: LIGHT COVER | D19: 2.46 | E19: 100 | F19: 170 | G19: =_xlfn.IFNA(VLOOKUP(データ!B19,INVOICE!$B$33:$K$50,6,FALSE),0) -> 0 | H19: =ROUNDUP(G19/F19,0) -> 0 | I19: =G19*E19/1000 -> 0 | K19: =H19*0.7 -> 0 | L19: =K19+J19+I19 -> 0 | M19: 26 | N19: pcs | O19: 17.5mm x 28.8mm x 717mm
B20: LDBA045101-2 | C20: DOOR CENTER SASH-S500 | D20: 7.94 | E20: 414 | F20: 40 | G20: =_xlfn.IFNA(VLOOKUP(データ!B20,INVOICE!$B$33:$K$50,6,FALSE),0) -> 0 | H20: =ROUNDUP(G20/F20,0) -> 0 | I20: =G20*E20/1000 -> 0 | K20: =H20*0.7 -> 0 | L20: =K20+J20+I20 -> 0 | M20: 28 | N20: pcs
B21: LDBA045101-3 | C21: DOOR CENTER SASH-S500H | D21: 7.94 | E21: 414 | F21: 40 | G21: =_xlfn.IFNA(VLOOKUP(データ!B21,INVOICE!$B$33:$K$50,6,FALSE),0) -> 640 | H21: =ROUNDUP(G21/F21,0) -> 16 | I21: =G21*E21/1000 -> 264.96 | K21: =H21*0.7 -> 11.2 | L21: =K21+J21+I21 -> 276.16 | M21: 28 | N21: pcs
B22: LDBA044901-2 | C22: DOOR OUTER SASH R -S500 | D22: 11.04 | E22: 470 | F22: 42 | G22: =_xlfn.IFNA(VLOOKUP(データ!B22,INVOICE!$B$33:$K$50,6,FALSE),0) -> 329 | H22: =ROUNDUP(G22/F22,0) -> 8 | I22: =G22*E22/1000 -> 154.63 | K22: =H22*0.7 -> 5.6 | L22: =K22+J22+I22 -> 160.23 | M22: 30 | N22: pcs
B23: LDBA044902-0 | C23: DOOR OUTER SASH R -S500H | D23: 11.04 | E23: 470 | F23: 42 | G23: =_xlfn.IFNA(VLOOKUP(データ!B23,INVOICE!$B$33:$K$50,6,FALSE),0) -> 0 | H23: =ROUNDUP(G23/F23,0) -> 0 | I23: =G23*E23/1000 -> 0 | K23: =H23*0.7 -> 0 | L23: =K23+J23+I23 -> 0 | M23: 30 | N23: pcs
B24: LDBA045001-2 | C24: DOOR OUTER SASH L-S500 | D24: 11.04 | E24: 470 | F24: 42 | G24: =_xlfn.IFNA(VLOOKUP(データ!B24,INVOICE!$B$33:$K$50,6,FALSE),0) -> 331 | H24: =ROUNDUP(G24/F24,0) -> 8 | I24: =G24*E24/1000 -> 155.57 | K24: =H24*0.7 -> 5.6 | L24: =K24+J24+I24 -> 161.17 | M24: 32 | N24: pcs
B25: LDBA045002-0 | C25: DOOR OUTER SASH L-S500H | D25: 11.04 | E25: 470 | F25: 42 | G25: =_xlfn.IFNA(VLOOKUP(データ!B25,INVOICE!$B$33:$K$50,6,FALSE),0) -> 0 | H25: =ROUNDUP(G25/F25,0) -> 0 | I25: =G25*E25/1000 -> 0 | K25: =H25*0.7 -> 0 | L25: =K25+J25+I25 -> 0 | M25: 32 | N25: pcs
A26: =#REF!+1 -> #REF! | B26: LDBA053500-0 | C26: LIGHT COVER-S500H | D26: 2.81 | E26: 90 | F26: 170 | G26: =_xlfn.IFNA(VLOOKUP(データ!B26,INVOICE!$B$33:$K$50,6,FALSE),0) -> 300 | H26: =ROUNDUP(G26/F26,0) -> 2 | I26: =G26*E26/1000 -> 27 | J26: =G26*E26/1000 -> 27 | K26: =H26*0.7 -> 1.4 | L26: =H26*0.7 -> 1.4 | M26: =L26+K26+J26 -> 29.8 | N26: pcs
A27: =A26+1 -> #REF! | B27: LDBA053601-1 | C27: DOOR UPPER SASH L-S500H | D27: 4.79 | E27: 255 | F27: 80 | G27: =_xlfn.IFNA(VLOOKUP(データ!B27,INVOICE!$B$33:$K$50,6,FALSE),0) -> 0 | H27: =ROUNDUP(G27/F27,0) -> 0 | I27: =G27*E27/1000 -> 0 | J27: =G27*E27/1000 -> 0 | K27: =H27*0.7 -> 0 | L27: =H27*0.7 -> 0 | M27: =L27+K27+J27 -> 0 | N27: pcs
A28: =A27+1 -> #REF! | B28: LDBA053700-0 | C28: DOOR LOWER SASH L-S500H | D28: 6.6 | E28: 169 | F28: 50 | G28: =_xlfn.IFNA(VLOOKUP(データ!B28,INVOICE!$B$33:$K$50,6,FALSE),0) -> 300 | H28: =ROUNDUP(G28/F28,0) -> 6 | I28: =G28*E28/1000 -> 50.7 | J28: =G28*E28/1000 -> 50.7 | K28: =H28*0.7 -> 4.2 | L28: =H28*0.7 -> 4.2 | M28: =L28+K28+J28 -> 59.1 | N28: pcs
A29: =A28+1 -> #REF! | B29: LDBA053800-0 | C29: DOOR LOWER SASH R-S500H | D29: 7.61 | E29: 167 | F29: 50 | G29: =_xlfn.IFNA(VLOOKUP(データ!B29,INVOICE!$B$33:$K$50,6,FALSE),0) -> 300 | H29: =ROUNDUP(G29/F29,0) -> 6 | I29: =G29*E29/1000 -> 50.1 | J29: =G29*E29/1000 -> 50.1 | K29: =H29*0.7 -> 4.2 | L29: =H29*0.7 -> 4.2 | M29: =L29+K29+J29 -> 58.5 | N29: pcs
A30: =A29+1 -> #REF! | B30: LDBA053900-1 | C30: RAIL TOP-S500H | D30: 6.13 | E30: 348 | F30: 40 | G30: =_xlfn.IFNA(VLOOKUP(データ!B30,INVOICE!$B$33:$K$50,6,FALSE),0) -> 0 | H30: =ROUNDUP(G30/F30,0) -> 0 | I30: =G30*E30/1000 -> 0 | J30: =G30*E30/1000 -> 0 | K30: =H30*0.7 -> 0 | L30: =H30*0.7 -> 0 | M30: =L30+K30+J30 -> 0 | N30: pcs
A31: =A30+1 -> #REF! | B31: LDBA054000-2 | C31: RAIL BOTTOM-S500H | D31: 9.87 | E31: 545 | F31: 46 | G31: =_xlfn.IFNA(VLOOKUP(データ!B31,INVOICE!$B$33:$K$50,6,FALSE),0) -> 0 | H31: =ROUNDUP(G31/F31,0) -> 0 | I31: =G31*E31/1000 -> 0 | J31: =G31*E31/1000 -> 0 | K31: =H31*0.7 -> 0 | L31: =H31*0.7 -> 0 | M31: =L31+K31+J31 -> 0 | N31: pcs
A32: =A31+1 -> #REF! | B32: LDBA064301-1 | C32: DOOR UPPER SASH R-S500H | D32: 4.79 | E32: 233 | F32: 80 | G32: =_xlfn.IFNA(VLOOKUP(データ!B32,INVOICE!$B$33:$K$50,6,FALSE),0) -> 0 | H32: =ROUNDUP(G32/F32,0) -> 0 | I32: =G32*E32/1000 -> 0 | J32: =G32*E32/1000 -> 0 | K32: =H32*0.7 -> 0 | L32: =H32*0.7 -> 0 | M32: =L32+K32+J32 -> 0 | N32: pcs
A33: =A32+1 -> #REF! | B33: LDBA045101-1 | C33: DOOR CENTER SASH-S500H | D33: 7.22 | E33: 414 | F33: 40 | G33: =_xlfn.IFNA(VLOOKUP(データ!B33,INVOICE!$B$33:$K$50,6,FALSE),0) -> 0 | H33: =ROUNDUP(G33/F33,0) -> 0 | I33: =G33*E33/1000 -> 0 | J33: =G33*E33/1000-0.01 -> -0.01 | K33: =H33*0.7 -> 0 | L33: =H33*0.7 -> 0 | M33: =L33+K33+J33 -> -0.01 | N33: pcs
A34: =A33+1 -> #REF! | B34: LDBA053601-2 | C34: DOOR UPPER SASH L-S500H | D34: 5.01 | E34: 233 | F34: 80 | G34: =_xlfn.IFNA(VLOOKUP(データ!B34,INVOICE!$B$33:$K$50,6,FALSE),0) -> 300 | H34: =ROUNDUP(G34/F34,0) -> 4 | I34: =G34*E34/1000 -> 69.9 | J34: =G34*E34/1000 -> 69.9 | K34: =H34*0.7 -> 2.8 | L34: =H34*0.7 -> 2.8 | M34: =L34+K34+J34 -> 75.5 | N34: pcs
A35: =A34+1 -> #REF! | B35: LDBA064301-2 | C35: DOOR UPPER SASH R-S500H | D35: 5.01 | E35: 233 | F35: 80 | G35: =_xlfn.IFNA(VLOOKUP(データ!B35,INVOICE!$B$33:$K$50,6,FALSE),0) -> 300 | H35: =ROUNDUP(G35/F35,0) -> 4 | I35: =G35*E35/1000 -> 69.9 | J35: =G35*E35/1000 -> 69.9 | K35: =H35*0.7 -> 2.8 | L35: =H35*0.7 -> 2.8 | M35: =L35+K35+J35 -> 75.5 | N35: pcs
A36: =A35+1 -> #REF! | B36: LDBA053603-0 | C36: DOOR UPPER SASH L-S150H | D36: 4.59 | E36: 233 | F36: 80 | G36: =_xlfn.IFNA(VLOOKUP(データ!B36,INVOICE!$B$33:$K$50,6,FALSE),0) -> 300 | H36: =ROUNDUP(G36/F36,0) -> 4 | I36: =G36*E36/1000 -> 69.9 | J36: =G36*E36/1000 -> 69.9 | K36: =H36*0.7 -> 2.8 | L36: =H36*0.7 -> 2.8 | M36: =L36+K36+J36 -> 75.5 | N36: pcs
A37: =A36+1 -> #REF! | B37: LDBA064303-0 | C37: DOOR UPPER SASH R-S150H | D37: 4.59 | E37: 233 | F37: 80 | G37: =_xlfn.IFNA(VLOOKUP(データ!B37,INVOICE!$B$33:$K$50,6,FALSE),0) -> 300 | H37: =ROUNDUP(G37/F37,0) -> 4 | I37: =G37*E37/1000 -> 69.9 | J37: =G37*E37/1000 -> 69.9 | K37: =H37*0.7 -> 2.8 | L37: =H37*0.7 -> 2.8 | M37: =L37+K37+J37 -> 75.5 | N37: pcs
A38: =A37+1 -> #REF! | B38: LDBA060501-1 | C38: RAIL TOP S1200H | D38: 15.07 | E38: 909 | F38: 22 | G38: =_xlfn.IFNA(VLOOKUP(データ!B38,INVOICE!$B$33:$K$50,6,FALSE),0) -> 80 | H38: =ROUNDUP(G38/F38,0) -> 4 | I38: =G38*E38/1000 -> 72.72 | J38: =G38*E38/1000 -> 72.72 | K38: =H38*0.7 -> 2.8 | L38: =H38*0.7 -> 2.8 | M38: =L38+K38+J38 -> 78.32 | N38: pcs
A39: =A38+1 -> #REF! | B39: LDBA087401-0 | C39: RAIL BOTTOM | D39: 17.38 | E39: 1105 | F39: 20 | G39: =_xlfn.IFNA(VLOOKUP(データ!B39,INVOICE!$B$33:$K$50,6,FALSE),0) -> 0 | H39: =ROUNDUP(G39/F39,0) -> 0 | I39: =G39*E39/1000 -> 0 | J39: =G39*E39/1000 -> 0 | K39: =H39*0.7 -> 0 | L39: =H39*0.7 -> 0 | M39: =L39+K39+J39 -> 0 | N39: pcs
A40: =A39+1 -> #REF! | B40: LDBA053602-1 | C40: DOOR UPPER SASH L-S1000H | D40: 10.14 | E40: 322 | F40: 36 | G40: =_xlfn.IFNA(VLOOKUP(データ!B40,INVOICE!$B$33:$K$50,6,FALSE),0) -> 0 | H40: =ROUNDUP(G40/F40,0) -> 0 | I40: =G40*E40/1000 -> 0 | J40: =G40*E40/1000 -> 0 | K40: =H40*0.7 -> 0 | L40: =H40*0.7 -> 0 | M40: =L40+K40+J40 -> 0 | N40: pcs
A41: =A40+1 -> #REF! | B41: LDBA064302-1 | C41: DOOR UPPER SASH R-S1000H | D41: 10.14 | E41: 322 | F41: 36 | G41: =_xlfn.IFNA(VLOOKUP(データ!B41,INVOICE!$B$33:$K$50,6,FALSE),0) -> 0 | H41: =ROUNDUP(G41/F41,0) -> 0 | I41: =G41*E41/1000 -> 0 | J41: =G41*E41/1000 -> 0 | K41: =H41*0.7 -> 0 | L41: =H41*0.7 -> 0 | M41: =L41+K41+J41 -> 0 | N41: pcs
...

Sheet quy cách palet
C2: Số lượng | D2: Quy cách đóng thùng | E2: Số lượng thùng /palet
A3: LDBA043800-1 | B3: RAIL TOP | C3: =VLOOKUP(A3,INVOICE!$B$33:$G$50,6,FALSE) -> #N/A | D3: 40 | E3: 18 | F3: 6 | G3: =C3/D3/E3 -> #N/A | H3: =ROUNDUP(G3,0) -> #N/A
A4: LDBA043900-1 | B4: RAIL BOTTOM | C4: =VLOOKUP(A4,INVOICE!$B$33:$G$50,6,FALSE) -> #N/A | D4: 46 | E4: 18 | F4: 6 | G4: =C4/D4/E4 -> #N/A | H4: =ROUNDUP(G4,0) -> #N/A
A5: LDBA044000-0 | B5: RAIL SIDE | C5: =VLOOKUP(A5,INVOICE!$B$33:$G$50,6,FALSE) -> #N/A | D5: 68 | E5: 18 | F5: 6 | G5: =C5/D5/E5 -> #N/A | H5: =ROUNDUP(G5,0) -> #N/A
A6: LDBA044100-0 | B6: RAIL SIDE | C6: =VLOOKUP(A6,INVOICE!$B$33:$G$50,6,FALSE) -> #N/A | D6: 34 | E6: 24 | F6: 8 | G6: =C6/D6/E6 -> #N/A | H6: =ROUNDUP(G6,0) -> #N/A
A7: LDBA044200-2 | B7: DOOR UPPER SASH | C7: =VLOOKUP(A7,INVOICE!$B$33:$G$50,6,FALSE) -> #N/A | D7: 51 | E7: 32 | F7: 8 | G7: =C7/D7/E7 -> #N/A | H7: =ROUNDUP(G7,0) -> #N/A
A8: LDBA044400-3 | B8: DOOR LOWER SASH R | C8: =VLOOKUP(A8,INVOICE!$B$33:$G$50,6,FALSE) -> #N/A | D8: 26 | E8: 32 | F8: 8 | G8: =C8/D8/E8 -> #N/A | H8: =ROUNDUP(G8,0) -> #N/A
A9: LDBA044500-3 | B9: DOOR LOWER SASH L | C9: =VLOOKUP(A9,INVOICE!$B$33:$G$50,6,FALSE) -> #N/A | D9: 26 | E9: 32 | F9: 8 | G9: =C9/D9/E9 -> #N/A | H9: =ROUNDUP(G9,0) -> #N/A
A10: LDBA044600-2 | B10: DOOR OUTER SASH R | C10: =VLOOKUP(A10,INVOICE!$B$33:$G$50,6,FALSE) -> #N/A | D10: 60 | E10: 18 | F10: 6 | G10: =C10/D10/E10 -> #N/A | H10: =ROUNDUP(G10,0) -> #N/A
A11: LDBA044700-3 | B11: DOOR OUTER SASH L | C11: =VLOOKUP(A11,INVOICE!$B$33:$G$50,6,FALSE) -> #N/A | D11: 60 | E11: 18 | F11: 6 | G11: =C11/D11/E11 -> #N/A | H11: =ROUNDUP(G11,0) -> #N/A
A12: LDBA044800-5 | B12: DOOR CENTER SASH | C12: =VLOOKUP(A12,INVOICE!$B$33:$G$50,6,FALSE) -> #N/A | D12: 70 | E12: 18 | F12: 6 | G12: =C12/D12/E12 -> #N/A | H12: =ROUNDUP(G12,0) -> #N/A
A13: LDBA044900-2 | B13: DOOR OUTER SASH R | C13: =VLOOKUP(A13,INVOICE!$B$33:$G$50,6,FALSE) -> #N/A | D13: 42 | E13: 24 | F13: 8 | G13: =C13/D13/E13 -> #N/A | H13: =ROUNDUP(G13,0) -> #N/A
A14: LDBA045000-3 | B14: DOOR OUTER SASH L | C14: =VLOOKUP(A14,INVOICE!$B$33:$G$50,6,FALSE) -> #N/A | D14: 42 | E14: 24 | F14: 8 | G14: =C14/D14/E14 -> #N/A | H14: =ROUNDUP(G14,0) -> #N/A
... A16: LDBA043601-0 | B16: LIGHT COVER | C16: =VLOOKUP(A16,INVOICE!$B$33:$G$50,6,FALSE) -> #N/A | D16: 170 | E16: 21 | F16: 7 | G16: =C16/D16/E16 -> #N/A | H16: =ROUNDUP(G16,0) -> #N/A
