Workbook

Sheet INVOICE
A1: INVOICE
H5: インボイス作成日（Date): 24/11/2025
A7: 依頼住 (Shipper Address) | H7: Invoice No [Invoice No]
A9: MASUDA VINYL VIETNAM CO.,LTD
A10: LOT NO1 DONG VANG DINH TRAM INDUSTRIAL ZONE | H10: (原産国) Country of Origin | J10: (仕向先国名) Country of Destination
A11: NENH WARD BAC NINH PROVINCE
A12: TEL : 0204 3662 777 | H12: VIETNAM | J12: INDONESIA
A13: FAX : 0204 3662 825
H14: Invoice will be closed on delivery day and payment after 60days
A15: 荷受人(Consigneer)
A18: PT. Sumitronics Indonesia
A19: KAWASAN INDUSTRIAL EJIP PLOT 1E-2 SUKARESMI CIKARANG SELATAN | H19: 備考 (Remark):
A21: TEL :62-21-8975220 ext : 252 | H21: P | I21: 有償（Commerical Value)
A22: TAX ID: 001.558.251.3-056.000 | I22: 無償（No Commerical Value)
A24: From (発地国) | I24: 贈物（Gift)
A25: BACNINH VIETNAM | I25: 商品見本（ Sample, No Commercial Value )
A26: To (着地国) | I26: その他（Other)
A27: JAKARTA INDONESIA
A29: 品番 ( Part No) | D29: 品名 (Part Name) | E29: 注文書No PO No | F29: 単位 （Unit） | G29: 数量 （Quantity) | H29: 単価 （Unit Price） USD | J29: 合計 （Total Amount) USD
A33: 1 | B33: LDBA043800-2 | D33: =VLOOKUP(B33,#REF!,2,FALSE) -> #REF! | E33: PHC-2025100007 | F33: =VLOOKUP(B33,#REF!,13,FALSE) -> #REF! | G33: 300 | H33: =VLOOKUP(B33,#REF!,3,FALSE) -> #REF! | J33: =H33*G33 -> #REF!
A34: =A33+1 -> 2 | B34: LDBA043900-2 | D34: =VLOOKUP(B34,#REF!,2,FALSE) -> #REF! | E34: PHC-2025100007 | F34: =VLOOKUP(B34,#REF!,13,FALSE) -> #REF! | G34: 300 | H34: =VLOOKUP(B34,#REF!,3,FALSE) -> #REF! | J34: =H34*G34 -> #REF!
A35: =A34+1 -> 3 | B35: LDBA044901-2 | D35: =VLOOKUP(B35,#REF!,2,FALSE) -> #REF! | E35: PHC-2025100019 | F35: =VLOOKUP(B35,#REF!,13,FALSE) -> #REF! | G35: 329 | H35: =VLOOKUP(B35,#REF!,3,FALSE) -> #REF! | J35: =H35*G35 -> #REF!
A36: =A35+1 -> 4 | B36: LDBA045001-2 | D36: =VLOOKUP(B36,#REF!,2,FALSE) -> #REF! | E36: PHC-2025100019 | F36: =VLOOKUP(B36,#REF!,13,FALSE) -> #REF! | G36: 331 | H36: =VLOOKUP(B36,#REF!,3,FALSE) -> #REF! | J36: =H36*G36 -> #REF!
A37: =A36+1 -> 5 | B37: LDBA045101-3 | D37: =VLOOKUP(B37,#REF!,2,FALSE) -> #REF! | E37: PHC-2025100007 PHC-2025100019 | F37: =VLOOKUP(B37,#REF!,13,FALSE) -> #REF! | G37: 640 | H37: =VLOOKUP(B37,#REF!,3,FALSE) -> #REF! | J37: =H37*G37 -> #REF!
A38: =A37+1 -> 6 | B38: LDBA053601-2 | D38: =VLOOKUP(B38,#REF!,2,FALSE) -> #REF! | E38: PHC-2025100019 | F38: =VLOOKUP(B38,#REF!,13,FALSE) -> #REF! | G38: 300 | H38: =VLOOKUP(B38,#REF!,3,FALSE) -> #REF! | J38: =H38*G38 -> #REF!
A39: =A38+1 -> 7 | B39: LDBA064301-2 | D39: =VLOOKUP(B39,#REF!,2,FALSE) -> #REF! | E39: PHC-2025100007 | F39: =VLOOKUP(B39,#REF!,13,FALSE) -> #REF! | G39: 300 | H39: =VLOOKUP(B39,#REF!,3,FALSE) -> #REF! | J39: =H39*G39 -> #REF!
A40: =A39+1 -> 8 | B40: LDBA053603-0 | D40: =VLOOKUP(B40,#REF!,2,FALSE) -> #REF! | E40: PHC-2025100019 | F40: =VLOOKUP(B40,#REF!,13,FALSE) -> #REF! | G40: 300 | H40: =VLOOKUP(B40,#REF!,3,FALSE) -> #REF! | J40: =H40*G40 -> #REF!
A41: =A40+1 -> 9 | B41: LDBA064303-0 | D41: =VLOOKUP(B41,#REF!,2,FALSE) -> #REF! | E41: PHC-2025100019 | F41: =VLOOKUP(B41,#REF!,13,FALSE) -> #REF! | G41: 300 | H41: =VLOOKUP(B41,#REF!,3,FALSE) -> #REF! | J41: =H41*G41 -> #REF!
A42: =A41+1 -> 10 | B42: LDBA053700-0 | D42: =VLOOKUP(B42,#REF!,2,FALSE) -> #REF! | E42: PHC-2025100019 | F42: =VLOOKUP(B42,#REF!,13,FALSE) -> #REF! | G42: 300 | H42: =VLOOKUP(B42,#REF!,3,FALSE) -> #REF! | J42: =H42*G42 -> #REF!
A43: =A42+1 -> 11 | B43: LDBA053800-0 | D43: =VLOOKUP(B43,#REF!,2,FALSE) -> #REF! | E43: PHC-2025100019 | F43: =VLOOKUP(B43,#REF!,13,FALSE) -> #REF! | G43: 300 | H43: =VLOOKUP(B43,#REF!,3,FALSE) -> #REF! | J43: =H43*G43 -> #REF!
A44: =A43+1 -> 12 | B44: LDBA061200-0 | D44: =VLOOKUP(B44,#REF!,2,FALSE) -> #REF! | E44: PHC-2025100063 PHC-2023060092 | F44: =VLOOKUP(B44,#REF!,13,FALSE) -> #REF! | G44: 323 | H44: =VLOOKUP(B44,#REF!,3,FALSE) -> #REF! | J44: =H44*G44 -> #REF!
A45: =A44+1 -> 13 | B45: LDBA061300-0 | D45: =VLOOKUP(B45,#REF!,2,FALSE) -> #REF! | E45: PHC-2023060092 | F45: =VLOOKUP(B45,#REF!,13,FALSE) -> #REF! | G45: 6 | H45: =VLOOKUP(B45,#REF!,3,FALSE) -> #REF! | J45: =H45*G45 -> #REF!
... A49: =A48+1 -> 17 | B49: LDBA060501-1 | D49: =VLOOKUP(B49,#REF!,2,FALSE) -> #REF! | E49: PHC-2024070112 | F49: =VLOOKUP(B49,#REF!,13,FALSE) -> #REF! | G49: 80 | H49: =VLOOKUP(B49,#REF!,3,FALSE) -> #REF! | J49: =H49*G49 -> #REF!
A50: =A49+1 -> 18
A51: 合計 （Total) | J51: =SUM(J33:K50) -> #REF!
A53: Terms: FOB HAI PHONG VIETNAM Incoterms® 2020 | H53: 署名（ Singnature )
A54: 原産国 (Country of Origin) : VIETNAM

Sheet PACKING LIST
A1: PACKING LIST
I5: =INVOICE!H5 -> インボイス作成日（Date): 24/11/2025
A8: 依頼住 (Shipper Address) | I8: =INVOICE!H7 -> Invoice No [Invoice No]
A10: MASUDA VINYL VIETNAM CO.,LTD
A11: LOT NO1 DONG VANG DINH TRAM INDUSTRIAL ZONE | I11: (原産国) Country of Origin | L11: (仕向先国名) Country of Destination
A12: NENH WARD BAC NINH PROVINCE
A13: TEL : 0204 3662 777 | I13: VIETNAM | L13: =INVOICE!J12 -> INDONESIA
A14: FAX : 0204 3662 825 | I14: 支払条件 (Terms of Payment)
I15: =INVOICE!H14 -> Invoice will be closed on delivery day and payment after 60days
A17: 荷受人(Consigneer)
A20: =INVOICE!A18 -> PT. Sumitronics Indonesia | I20: 備考 (Remark):
A21: =INVOICE!A19 -> KAWASAN INDUSTRIAL EJIP PLOT 1E-2 SUKARESMI CIKARANG SELATAN | I21: P | J21: 有償（Commerical Value)
A22: =IF(INVOICE!A20="","",INVOICE!A20) | J22: 無償（No Commerical Value)
A23: =INVOICE!A21 -> TEL :62-21-8975220 ext : 252
J24: 贈物（Gift)
J25: 商品見本（ Sample, No Commercial Value )
A26: From (発地国) | J26: その他（Other)
A27: BACNINH VIETNAM
A28: To (着地国)
A29: =INVOICE!A27 -> JAKARTA INDONESIA
A31: =INVOICE!A29 -> 品番 ( Part No) | D31: =INVOICE!D29 -> 品名 (Part Name) | E31: 注文書No PO No | F31: 単位 （Unit） | G31: 数量 （Quantity) | H31: 梱包 （Packing） | J31: 箱数 ( Number of Boxs) | K31: パレット数 ( Number of Pallets) | L31: 正味重量 (Net weight) | M31: 総重量 (Gross weight)
A35: 1 | B35: =INVOICE!B33 -> LDBA043800-2 | D35: =INVOICE!D33 -> #REF! | E35: =INVOICE!E33 -> PHC-2025100007 | F35: =INVOICE!F33 -> #REF! | G35: =INVOICE!G33 -> 300 | H35: =_xlfn.XLOOKUP(B35,データ!B:B,データ!F:F,"") -> 40 | J35: =IFERROR(ROUNDUP(G35/H35,0),"") -> 8 | K35: 7 | L35: =IFERROR(G35*O35/1000,"") -> 0 | M35: =IFERROR(L35+J35*0.77+10,"") -> 16.16
A36: =A35+1 -> 2 | B36: =INVOICE!B34 -> LDBA043900-2 | D36: =INVOICE!D34 -> #REF! | E36: =INVOICE!E34 -> PHC-2025100007 | F36: =INVOICE!F34 -> #REF! | G36: =INVOICE!G34 -> 300 | H36: =_xlfn.XLOOKUP(B36,データ!B:B,データ!F:F,"") -> 46 | J36: =IFERROR(ROUNDUP(G36/H36,0),"") -> 7 | L36: =IFERROR(G36*O36/1000,"") -> 0 | M36: =IFERROR(L36+J36*0.77+10,"") -> 15.39
A37: =A36+1 -> 3 | B37: =INVOICE!B35 -> LDBA044901-2 | D37: =INVOICE!D35 -> #REF! | E37: =INVOICE!E35 -> PHC-2025100019 | F37: =INVOICE!F35 -> #REF! | G37: =INVOICE!G35 -> 329 | H37: =_xlfn.XLOOKUP(B37,データ!B:B,データ!F:F,"") -> 42 | J37: =IFERROR(ROUNDUP(G37/H37,0),"") -> 8 | L37: =IFERROR(G37*O37/1000,"") -> 0 | M37: =IFERROR(L37+J37*0.77+10,"") -> 16.16
A38: =A37+1 -> 4 | B38: =INVOICE!B36 -> LDBA045001-2 | D38: =INVOICE!D36 -> #REF! | E38: =INVOICE!E36 -> PHC-2025100019 | F38: =INVOICE!F36 -> #REF! | G38: =INVOICE!G36 -> 331 | H38: =_xlfn.XLOOKUP(B38,データ!B:B,データ!F:F,"") -> 42 | J38: =IFERROR(ROUNDUP(G38/H38,0),"") -> 8 | L38: =IFERROR(G38*O38/1000,"") -> 0 | M38: =IFERROR(L38+J38*0.77+10,"") -> 16.16
A39: =A38+1 -> 5 | B39: =INVOICE!B37 -> LDBA045101-3 | D39: =INVOICE!D37 -> #REF! | E39: =INVOICE!E37 -> PHC-2025100007 PHC-2025100019 | F39: =INVOICE!F37 -> #REF! | G39: =INVOICE!G37 -> 640 | H39: =_xlfn.XLOOKUP(B39,データ!B:B,データ!F:F,"") -> 40 | J39: =IFERROR(ROUNDUP(G39/H39,0),"") -> 16 | L39: =IFERROR(G39*O39/1000,"") -> 0 | M39: =IFERROR(L39+J39*0.77+10,"") -> 22.32
A40: =A39+1 -> 6 | B40: =INVOICE!B38 -> LDBA053601-2 | D40: =INVOICE!D38 -> #REF! | E40: =INVOICE!E38 -> PHC-2025100019 | F40: =INVOICE!F38 -> #REF! | G40: =INVOICE!G38 -> 300 | H40: =_xlfn.XLOOKUP(B40,データ!B:B,データ!F:F,"") -> 80 | J40: =IFERROR(ROUNDUP(G40/H40,0),"") -> 4 | L40: =IFERROR(G40*O40/1000,"") -> 0 | M40: =IFERROR(L40+J40*0.77+10,"") -> 13.08
A41: =A40+1 -> 7 | B41: =INVOICE!B39 -> LDBA064301-2 | D41: =INVOICE!D39 -> #REF! | E41: =INVOICE!E39 -> PHC-2025100007 | F41: =INVOICE!F39 -> #REF! | G41: =INVOICE!G39 -> 300 | H41: =_xlfn.XLOOKUP(B41,データ!B:B,データ!F:F,"") -> 80 | J41: =IFERROR(ROUNDUP(G41/H41,0),"") -> 4 | L41: =IFERROR(G41*O41/1000,"") -> 0 | M41: =IFERROR(L41+J41*0.77+10,"") -> 13.08
A42: =A41+1 -> 8 | B42: =INVOICE!B40 -> LDBA053603-0 | D42: =INVOICE!D40 -> #REF! | E42: =INVOICE!E40 -> PHC-2025100019 | F42: =INVOICE!F40 -> #REF! | G42: =INVOICE!G40 -> 300 | H42: =_xlfn.XLOOKUP(B42,データ!B:B,データ!F:F,"") -> 80 | J42: =IFERROR(ROUNDUP(G42/H42,0),"") -> 4 | L42: =IFERROR(G42*O42/1000,"") -> 0 | M42: =IFERROR(L42+J42*0.77+10,"") -> 13.08
A43: =A42+1 -> 9 | B43: =INVOICE!B41 -> LDBA064303-0 | D43: =INVOICE!D41 -> #REF! | E43: =INVOICE!E41 -> PHC-2025100019 | F43: =INVOICE!F41 -> #REF! | G43: =INVOICE!G41 -> 300 | H43: =_xlfn.XLOOKUP(B43,データ!B:B,データ!F:F,"") -> 80 | J43: =IFERROR(ROUNDUP(G43/H43,0),"") -> 4 | L43: =IFERROR(G43*O43/1000,"") -> 0 | M43: =IFERROR(L43+J43*0.77+10,"") -> 13.08
A44: =A43+1 -> 10 | B44: =INVOICE!B42 -> LDBA053700-0 | D44: =INVOICE!D42 -> #REF! | E44: =INVOICE!E42 -> PHC-2025100019 | F44: =INVOICE!F42 -> #REF! | G44: =INVOICE!G42 -> 300 | H44: =_xlfn.XLOOKUP(B44,データ!B:B,データ!F:F,"") -> 50 | J44: =IFERROR(ROUNDUP(G44/H44,0),"") -> 6 | L44: =IFERROR(G44*O44/1000,"") -> 0 | M44: =IFERROR(L44+J44*0.77+10,"") -> 14.62
A45: =A44+1 -> 11 | B45: =INVOICE!B43 -> LDBA053800-0 | D45: =INVOICE!D43 -> #REF! | E45: =INVOICE!E43 -> PHC-2025100019 | F45: =INVOICE!F43 -> #REF! | G45: =INVOICE!G43 -> 300 | H45: =_xlfn.XLOOKUP(B45,データ!B:B,データ!F:F,"") -> 50 | J45: =IFERROR(ROUNDUP(G45/H45,0),"") -> 6 | L45: =IFERROR(G45*O45/1000,"") -> 0 | M45: =IFERROR(L45+J45*0.77+10,"") -> 14.62
A46: =A45+1 -> 12 | B46: =INVOICE!B44 -> LDBA061200-0 | D46: =INVOICE!D44 -> #REF! | E46: =INVOICE!E44 -> PHC-2025100063 PHC-2023060092 | F46: =INVOICE!F44 -> #REF! | G46: =INVOICE!G44 -> 323 | H46: =_xlfn.XLOOKUP(B46,データ!B:B,データ!F:F,"") -> 20 | J46: =IFERROR(ROUNDUP(G46/H46,0),"") -> 17 | L46: =IFERROR(G46*O46/1000,"") -> 0 | M46: =IFERROR(L46+J46*0.77+10,"") -> 23.09
A47: =A46+1 -> 13 | B47: =INVOICE!B45 -> LDBA061300-0 | D47: =INVOICE!D45 -> #REF! | E47: =INVOICE!E45 -> PHC-2023060092 | F47: =INVOICE!F45 -> #REF! | G47: =INVOICE!G45 -> 6 | H47: =_xlfn.XLOOKUP(B47,データ!B:B,データ!F:F,"") -> 20 | J47: =IFERROR(ROUNDUP(G47/H47,0),"") -> 1 | L47: =IFERROR(G47*O47/1000,"") -> 0 | M47: =IFERROR(L47+J47*0.77+10,"") -> 10.77
... A51: =A50+1 -> 17 | B51: =INVOICE!B49 -> LDBA060501-1 | D51: =INVOICE!D49 -> #REF! | E51: =INVOICE!E49 -> PHC-2024070112 | F51: =INVOICE!F49 -> #REF! | G51: =INVOICE!G49 -> 80 | H51: =_xlfn.XLOOKUP(B51,データ!B:B,データ!F:F,"") -> 22 | J51: =IFERROR(ROUNDUP(G51/H51,0),"") -> 4 | L51: =IFERROR(G51*O51/1000,"") -> 0 | M51: =IFERROR(L51+J51*0.77+10,"") -> 13.08
A52: =A51+1 -> 18
A53: 合計 （Total) | G53: =SUM(G35:G52) -> 4742 | J53: =SUM(J35:J52) -> 110 | K53: =SUM(K35:K52) -> 7 | L53: =SUM(L35:L52) -> 0 | M53: =SUM(M35:M52) -> 254.7
A55: =INVOICE!A54 -> 原産国 (Country of Origin) : VIETNAM
A56: 郵便物の個数 ( Number of pieces) : | D56: =G53 -> 4742
A57: 総重量（Gross weight) Kg : | D57: =M53 -> 254.7 | I57: 署名（ Singnature )
...

Sheet データ
A2: No | B2: 品名 | D2: 単価 | E2: 重さ | F2: 梱包 | G2: 出荷数 | H2: 箱数 | I2: 使用材 | J2: 袋 | K2: 段ボール | L2: 総数量 | M2: Số lượng tối đa 1palet | N2: 単位 | O2: KT
A3: 1 | B3: LDBA043800-2 | C3: RAIL TOP | D3: 6.55 | E3: 412 | F3: 40 | G3: =_xlfn.IFNA(VLOOKUP(データ!B3,[1]INVOICE!$B$33:$K$50,6,FALSE),0) -> 300 | H3: =ROUNDUP(G3/F3,0) -> 8 | I3: =G3*E3/1000 -> 123.6 | K3: =H3*0.7 -> 5.6 | L3: =K3+J3+I3 -> 129.2 | M3: 18 | N3: pcs | O3: 78mm x 25mmx710mm
A4: 2 | B4: LDBA043900-1 | C4: RAIL BOTTOM | D4: 8.67 | E4: 412 | F4: 46 | G4: =_xlfn.IFNA(VLOOKUP(データ!B4,[1]INVOICE!$B$33:$K$50,6,FALSE),0) -> 0 | H4: =ROUNDUP(G4/F4,0) -> 0 | I4: =G4*E4/1000 -> 0 | K4: =H4*0.7 -> 0 | L4: =K4+J4+I4 -> 0 | M4: 18 | N4: pcs | O4: 33mm x 81mm x 749mm
A5: 3 | B5: LDBA043900-2 | C5: RAIL BOTTOM | D5: 9.88 | E5: 412 | F5: 46 | G5: =_xlfn.IFNA(VLOOKUP(データ!B5,[1]INVOICE!$B$33:$K$50,6,FALSE),0) -> 300 | H5: =ROUNDUP(G5/F5,0) -> 7 | I5: =G5*E5/1000 -> 123.6 | K5: =H5*0.7 -> 4.9 | L5: =K5+J5+I5 -> 128.5 | M5: 18 | N5: pcs | O5: 33mm x 81mm x 749mm
A6: =A5+1 -> 4 | B6: LDBA044000-0 | C6: RAIL SIDE | D6: 4.27 | E6: 360 | F6: 68 | G6: =_xlfn.IFNA(VLOOKUP(データ!B6,[1]INVOICE!$B$33:$K$50,6,FALSE),0) -> 0 | H6: =ROUNDUP(G6/F6,0) -> 0 | I6: =G6*E6/1000 -> 0 | K6: =H6*0.7 -> 0 | L6: =K6+J6+I6 -> 0 | M6: 18 | N6: pcs | O6: 15mm x 78mm x 727mm
A7: =A6+1 -> 5 | B7: LDBA044100-0 | C7: RAIL SIDE | D7: 7.8 | E7: 706 | F7: 34 | G7: =_xlfn.IFNA(VLOOKUP(データ!B7,[1]INVOICE!$B$33:$K$50,6,FALSE),0) -> 0 | H7: =ROUNDUP(G7/F7,0) -> 0 | I7: =G7*E7/1000 -> 0 | K7: =H7*0.7 -> 0 | L7: =K7+J7+I7 -> 0 | M7: 24 | N7: pcs | O7: 15mm x 78mm x 1724mm
A8: =A7+1 -> 6 | B8: LDBA044200-3 | C8: DOOR UPPER SASH | D8: 4.19 | E8: 156 | F8: 80 | G8: =_xlfn.IFNA(VLOOKUP(データ!B8,[1]INVOICE!$B$33:$K$50,6,FALSE),0) -> 0 | H8: =ROUNDUP(G8/F8,0) -> 0 | I8: =G8*E8/1000 -> 0 | K8: =H8*0.7 -> 0 | L8: =K8+J8+I8 -> 0 | M8: 32 | N8: pcs
A9: =A8+1 -> 7 | B9: LDBA044400-3 | C9: DOOR LOWER SASH R | D9: 6.22 | E9: 212 | F9: 26 | G9: =_xlfn.IFNA(VLOOKUP(データ!B9,[1]INVOICE!$B$33:$K$50,6,FALSE),0) -> 0 | H9: =ROUNDUP(G9/F9,0) -> 0 | I9: =G9*E9/1000 -> 0 | K9: =H9*0.7 -> 0 | L9: =K9+J9+I9 -> 0 | M9: 32 | N9: pcs | O9: 28mm x 70mm x 353mm
A10: =A9+1 -> 8 | B10: LDBA044500-3 | C10: DOOR LOWER SASH L | D10: 5.84 | E10: 212 | F10: 26 | G10: =_xlfn.IFNA(VLOOKUP(データ!B10,[1]INVOICE!$B$33:$K$50,6,FALSE),0) -> 0 | H10: =ROUNDUP(G10/F10,0) -> 0 | I10: =G10*E10/1000 -> 0 | K10: =H10*0.7 -> 0 | L10: =K10+J10+I10 -> 0 | M10: 32 | N10: pcs | O10: 28mm x 70mm x 353mm
B11: LDBA044600-6 | C11: DOOR OUTER SASH R | D11: 6.84 | E11: 250 | F11: 60 | G11: =_xlfn.IFNA(VLOOKUP(データ!B11,[1]INVOICE!$B$33:$K$50,6,FALSE),0) -> 0 | H11: =ROUNDUP(G11/F11,0) -> 0 | I11: =G11*E11/1000 -> 0 | K11: =H11*0.7 -> 0 | L11: =K11+J11+I11 -> 0 | M11: 19 | N11: pcs
B12: LDBA044700-7 | C12: DOOR OUTER SASH L | D12: 6.84 | E12: 250 | F12: 60 | G12: =_xlfn.IFNA(VLOOKUP(データ!B12,[1]INVOICE!$B$33:$K$50,6,FALSE),0) -> 0 | H12: =ROUNDUP(G12/F12,0) -> 0 | I12: =G12*E12/1000 -> 0 | K12: =H12*0.7 -> 0 | L12: =K12+J12+I12 -> 0 | M12: 21 | N12: pcs
A13: =#REF!+1 -> #REF! | B13: LDBA044800-7 | C13: DOOR CENTER SASH | D13: 4.27 | E13: 220 | F13: 70 | G13: =_xlfn.IFNA(VLOOKUP(データ!B13,[1]INVOICE!$B$33:$K$50,6,FALSE),0) -> 0 | H13: =ROUNDUP(G13/F13,0) -> 0 | I13: =G13*E13/1000 -> 0 | K13: =H13*0.7 -> 0 | L13: =K13+J13+I13 -> 0 | M13: 18 | N13: pcs
B14: LDBA044800-8 | C14: DOOR CENTER SASH | D14: 4.27 | E14: 220 | F14: 70 | G14: =_xlfn.IFNA(VLOOKUP(データ!B14,[1]INVOICE!$B$33:$K$50,6,FALSE),0) -> 0 | H14: =ROUNDUP(G14/F14,0) -> 0 | I14: =G14*E14/1000 -> 0 | K14: =H14*0.7 -> 0 | L14: =K14+J14+I14 -> 0 | M14: 19 | N14: pcs
B15: LDBA044800-9 | C15: DOOR CENTER SASH | D15: 4.27 | E15: 220 | F15: 70 | G15: =_xlfn.IFNA(VLOOKUP(データ!B15,[1]INVOICE!$B$33:$K$50,6,FALSE),0) -> 0 | H15: =ROUNDUP(G15/F15,0) -> 0 | I15: =G15*E15/1000 -> 0 | K15: =H15*0.7 -> 0 | L15: =K15+J15+I15 -> 0 | M15: 19 | N15: pcs
B16: LDBA093301-0 | C16: DOOR CENTER SASH | D16: 4.27 | E16: 220 | F16: 80 | G16: =_xlfn.IFNA(VLOOKUP(データ!B16,[1]INVOICE!$B$33:$K$50,6,FALSE),0) -> 13 | H16: =ROUNDUP(G16/F16,0) -> 1 | I16: =G16*E16/1000 -> 2.86 | K16: =H16*0.7 -> 0.7 | L16: =K16+J16+I16 -> 3.56 | M16: 19 | N16: pcs
A17: =A13+1 -> #REF! | B17: LDBA045100-7 | C17: DOOR CENTER SASH | D17: 7.94 | E17: 410 | F17: 40 | G17: =_xlfn.IFNA(VLOOKUP(データ!B17,[1]INVOICE!$B$33:$K$50,6,FALSE),0) -> 0 | H17: =ROUNDUP(G17/F17,0) -> 0 | I17: =G17*E17/1000 -> 0 | K17: =H17*0.7 -> 0 | L17: =K17+J17+I17 -> 0 | M17: 24 | N17: pcs
B18: LDBA045100-9 | C18: DOOR CENTER SASH | D18: 7.94 | E18: 410 | F18: 40 | G18: =_xlfn.IFNA(VLOOKUP(データ!B18,[1]INVOICE!$B$33:$K$50,6,FALSE),0) -> 0 | H18: =ROUNDUP(G18/F18,0) -> 0 | I18: =G18*E18/1000 -> 0 | K18: =H18*0.7 -> 0 | L18: =K18+J18+I18 -> 0 | M18: 25 | N18: pcs
A19: =A17+1 -> #REF! | B19: LDBA043601-0 | C19: LIGHT COVER | D19: 2.46 | E19: 100 | F19: 170 | G19: =_xlfn.IFNA(VLOOKUP(データ!B19,[1]INVOICE!$B$33:$K$50,6,FALSE),0) -> 0 | H19: =ROUNDUP(G19/F19,0) -> 0 | I19: =G19*E19/1000 -> 0 | K19: =H19*0.7 -> 0 | L19: =K19+J19+I19 -> 0 | M19: 26 | N19: pcs | O19: 17.5mm x 28.8mm x 717mm
B20: LDBA045101-2 | C20: DOOR CENTER SASH-S500 | D20: 7.94 | E20: 414 | F20: 40 | G20: =_xlfn.IFNA(VLOOKUP(データ!B20,[1]INVOICE!$B$33:$K$50,6,FALSE),0) -> 0 | H20: =ROUNDUP(G20/F20,0) -> 0 | I20: =G20*E20/1000 -> 0 | K20: =H20*0.7 -> 0 | L20: =K20+J20+I20 -> 0 | M20: 28 | N20: pcs
B21: LDBA045101-3 | C21: DOOR CENTER SASH-S500H | D21: 7.94 | E21: 414 | F21: 40 | G21: =_xlfn.IFNA(VLOOKUP(データ!B21,[1]INVOICE!$B$33:$K$50,6,FALSE),0) -> 640 | H21: =ROUNDUP(G21/F21,0) -> 16 | I21: =G21*E21/1000 -> 264.96 | K21: =H21*0.7 -> 11.2 | L21: =K21+J21+I21 -> 276.16 | M21: 28 | N21: pcs
B22: LDBA044901-2 | C22: DOOR OUTER SASH R -S500 | D22: 11.04 | E22: 470 | F22: 42 | G22: =_xlfn.IFNA(VLOOKUP(データ!B22,[1]INVOICE!$B$33:$K$50,6,FALSE),0) -> 329 | H22: =ROUNDUP(G22/F22,0) -> 8 | I22: =G22*E22/1000 -> 154.63 | K22: =H22*0.7 -> 5.6 | L22: =K22+J22+I22 -> 160.23 | M22: 30 | N22: pcs
B23: LDBA044902-0 | C23: DOOR OUTER SASH R -S500H | D23: 11.04 | E23: 470 | F23: 42 | G23: =_xlfn.IFNA(VLOOKUP(データ!B23,[1]INVOICE!$B$33:$K$50,6,FALSE),0) -> 0 | H23: =ROUNDUP(G23/F23,0) -> 0 | I23: =G23*E23/1000 -> 0 | K23: =H23*0.7 -> 0 | L23: =K23+J23+I23 -> 0 | M23: 30 | N23: pcs
B24: LDBA045001-2 | C24: DOOR OUTER SASH L-S500 | D24: 11.04 | E24: 470 | F24: 42 | G24: =_xlfn.IFNA(VLOOKUP(データ!B24,[1]INVOICE!$B$33:$K$50,6,FALSE),0) -> 331 | H24: =ROUNDUP(G24/F24,0) -> 8 | I24: =G24*E24/1000 -> 155.57 | K24: =H24*0.7 -> 5.6 | L24: =K24+J24+I24 -> 161.17 | M24: 32 | N24: pcs
B25: LDBA045002-0 | C25: DOOR OUTER SASH L-S500H | D25: 11.04 | E25: 470 | F25: 42 | G25: =_xlfn.IFNA(VLOOKUP(データ!B25,[1]INVOICE!$B$33:$K$50,6,FALSE),0) -> 0 | H25: =ROUNDUP(G25/F25,0) -> 0 | I25: =G25*E25/1000 -> 0 | K25: =H25*0.7 -> 0 | L25: =K25+J25+I25 -> 0 | M25: 32 | N25: pcs
A26: =#REF!+1 -> #REF! | B26: LDBA053500-0 | C26: LIGHT COVER-S500H | D26: 2.81 | E26: 90 | F26: 170 | G26: =_xlfn.IFNA(VLOOKUP(データ!B26,[1]INVOICE!$B$33:$K$50,6,FALSE),0) -> 300 | H26: =ROUNDUP(G26/F26,0) -> 2 | I26: =G26*E26/1000 -> 27 | J26: =G26*E26/1000 -> 27 | K26: =H26*0.7 -> 1.4 | L26: =H26*0.7 -> 1.4 | M26: =L26+K26+J26 -> 29.8 | N26: pcs
A27: =A26+1 -> #REF! | B27: LDBA053601-1 | C27: DOOR UPPER SASH L-S500H | D27: 4.79 | E27: 255 | F27: 80 | G27: =_xlfn.IFNA(VLOOKUP(データ!B27,[1]INVOICE!$B$33:$K$50,6,FALSE),0) -> 0 | H27: =ROUNDUP(G27/F27,0) -> 0 | I27: =G27*E27/1000 -> 0 | J27: =G27*E27/1000 -> 0 | K27: =H27*0.7 -> 0 | L27: =H27*0.7 -> 0 | M27: =L27+K27+J27 -> 0 | N27: pcs
A28: =A27+1 -> #REF! | B28: LDBA053700-0 | C28: DOOR LOWER SASH L-S500H | D28: 6.6 | E28: 169 | F28: 50 | G28: =_xlfn.IFNA(VLOOKUP(データ!B28,[1]INVOICE!$B$33:$K$50,6,FALSE),0) -> 300 | H28: =ROUNDUP(G28/F28,0) -> 6 | I28: =G28*E28/1000 -> 50.7 | J28: =G28*E28/1000 -> 50.7 | K28: =H28*0.7 -> 4.2 | L28: =H28*0.7 -> 4.2 | M28: =L28+K28+J28 -> 59.1 | N28: pcs
A29: =A28+1 -> #REF! | B29: LDBA053800-0 | C29: DOOR LOWER SASH R-S500H | D29: 7.61 | E29: 167 | F29: 50 | G29: =_xlfn.IFNA(VLOOKUP(データ!B29,[1]INVOICE!$B$33:$K$50,6,FALSE),0) -> 300 | H29: =ROUNDUP(G29/F29,0) -> 6 | I29: =G29*E29/1000 -> 50.1 | J29: =G29*E29/1000 -> 50.1 | K29: =H29*0.7 -> 4.2 | L29: =H29*0.7 -> 4.2 | M29: =L29+K29+J29 -> 58.5 | N29: pcs
A30: =A29+1 -> #REF! | B30: LDBA053900-1 | C30: RAIL TOP-S500H | D30: 6.13 | E30: 348 | F30: 40 | G30: =_xlfn.IFNA(VLOOKUP(データ!B30,[1]INVOICE!$B$33:$K$50,6,FALSE),0) -> 0 | H30: =ROUNDUP(G30/F30,0) -> 0 | I30: =G30*E30/1000 -> 0 | J30: =G30*E30/1000 -> 0 | K30: =H30*0.7 -> 0 | L30: =H30*0.7 -> 0 | M30: =L30+K30+J30 -> 0 | N30: pcs
A31: =A30+1 -> #REF! | B31: LDBA054000-2 | C31: RAIL BOTTOM-S500H | D31: 9.87 | E31: 545 | F31: 46 | G31: =_xlfn.IFNA(VLOOKUP(データ!B31,[1]INVOICE!$B$33:$K$50,6,FALSE),0) -> 0 | H31: =ROUNDUP(G31/F31,0) -> 0 | I31: =G31*E31/1000 -> 0 | J31: =G31*E31/1000 -> 0 | K31: =H31*0.7 -> 0 | L31: =H31*0.7 -> 0 | M31: =L31+K31+J31 -> 0 | N31: pcs
A32: =A31+1 -> #REF! | B32: LDBA064301-1 | C32: DOOR UPPER SASH R-S500H | D32: 4.79 | E32: 233 | F32: 80 | G32: =_xlfn.IFNA(VLOOKUP(データ!B32,[1]INVOICE!$B$33:$K$50,6,FALSE),0) -> 0 | H32: =ROUNDUP(G32/F32,0) -> 0 | I32: =G32*E32/1000 -> 0 | J32: =G32*E32/1000 -> 0 | K32: =H32*0.7 -> 0 | L32: =H32*0.7 -> 0 | M32: =L32+K32+J32 -> 0 | N32: pcs
A33: =A32+1 -> #REF! | B33: LDBA045101-1 | C33: DOOR CENTER SASH-S500H | D33: 7.22 | E33: 414 | F33: 40 | G33: =_xlfn.IFNA(VLOOKUP(データ!B33,[1]INVOICE!$B$33:$K$50,6,FALSE),0) -> 0 | H33: =ROUNDUP(G33/F33,0) -> 0 | I33: =G33*E33/1000 -> 0 | J33: =G33*E33/1000-0.01 -> -0.01 | K33: =H33*0.7 -> 0 | L33: =H33*0.7 -> 0 | M33: =L33+K33+J33 -> -0.01 | N33: pcs
A34: =A33+1 -> #REF! | B34: LDBA053601-2 | C34: DOOR UPPER SASH L-S500H | D34: 5.01 | E34: 233 | F34: 80 | G34: =_xlfn.IFNA(VLOOKUP(データ!B34,[1]INVOICE!$B$33:$K$50,6,FALSE),0) -> 300 | H34: =ROUNDUP(G34/F34,0) -> 4 | I34: =G34*E34/1000 -> 69.9 | J34: =G34*E34/1000 -> 69.9 | K34: =H34*0.7 -> 2.8 | L34: =H34*0.7 -> 2.8 | M34: =L34+K34+J34 -> 75.5 | N34: pcs
A35: =A34+1 -> #REF! | B35: LDBA064301-2 | C35: DOOR UPPER SASH R-S500H | D35: 5.01 | E35: 233 | F35: 80 | G35: =_xlfn.IFNA(VLOOKUP(データ!B35,[1]INVOICE!$B$33:$K$50,6,FALSE),0) -> 300 | H35: =ROUNDUP(G35/F35,0) -> 4 | I35: =G35*E35/1000 -> 69.9 | J35: =G35*E35/1000 -> 69.9 | K35: =H35*0.7 -> 2.8 | L35: =H35*0.7 -> 2.8 | M35: =L35+K35+J35 -> 75.5 | N35: pcs
A36: =A35+1 -> #REF! | B36: LDBA053603-0 | C36: DOOR UPPER SASH L-S150H | D36: 4.59 | E36: 233 | F36: 80 | G36: =_xlfn.IFNA(VLOOKUP(データ!B36,[1]INVOICE!$B$33:$K$50,6,FALSE),0) -> 300 | H36: =ROUNDUP(G36/F36,0) -> 4 | I36: =G36*E36/1000 -> 69.9 | J36: =G36*E36/1000 -> 69.9 | K36: =H36*0.7 -> 2.8 | L36: =H36*0.7 -> 2.8 | M36: =L36+K36+J36 -> 75.5 | N36: pcs
A37: =A36+1 -> #REF! | B37: LDBA064303-0 | C37: DOOR UPPER SASH R-S150H | D37: 4.59 | E37: 233 | F37: 80 | G37: =_xlfn.IFNA(VLOOKUP(データ!B37,[1]INVOICE!$B$33:$K$50,6,FALSE),0) -> 300 | H37: =ROUNDUP(G37/F37,0) -> 4 | I37: =G37*E37/1000 -> 69.9 | J37: =G37*E37/1000 -> 69.9 | K37: =H37*0.7 -> 2.8 | L37: =H37*0.7 -> 2.8 | M37: =L37+K37+J37 -> 75.5 | N37: pcs
A38: =A37+1 -> #REF! | B38: LDBA060501-1 | C38: RAIL TOP S1200H | D38: 15.07 | E38: 909 | F38: 22 | G38: =_xlfn.IFNA(VLOOKUP(データ!B38,[1]INVOICE!$B$33:$K$50,6,FALSE),0) -> 80 | H38: =ROUNDUP(G38/F38,0) -> 4 | I38: =G38*E38/1000 -> 72.72 | J38: =G38*E38/1000 -> 72.72 | K38: =H38*0.7 -> 2.8 | L38: =H38*0.7 -> 2.8 | M38: =L38+K38+J38 -> 78.32 | N38: pcs
A39: =A38+1 -> #REF! | B39: LDBA087401-0 | C39: RAIL BOTTOM | D39: 17.38 | E39: 1105 | F39: 20 | G39: =_xlfn.IFNA(VLOOKUP(データ!B39,[1]INVOICE!$B$33:$K$50,6,FALSE),0) -> 0 | H39: =ROUNDUP(G39/F39,0) -> 0 | I39: =G39*E39/1000 -> 0 | J39: =G39*E39/1000 -> 0 | K39: =H39*0.7 -> 0 | L39: =H39*0.7 -> 0 | M39: =L39+K39+J39 -> 0 | N39: pcs
A40: =A39+1 -> #REF! | B40: LDBA053602-1 | C40: DOOR UPPER SASH L-S1000H | D40: 10.14 | E40: 322 | F40: 36 | G40: =_xlfn.IFNA(VLOOKUP(データ!B40,[1]INVOICE!$B$33:$K$50,6,FALSE),0) -> 0 | H40: =ROUNDUP(G40/F40,0) -> 0 | I40: =G40*E40/1000 -> 0 | J40: =G40*E40/1000 -> 0 | K40: =H40*0.7 -> 0 | L40: =H40*0.7 -> 0 | M40: =L40+K40+J40 -> 0 | N40: pcs
A41: =A40+1 -> #REF! | B41: LDBA064302-1 | C41: DOOR UPPER SASH R-S1000H | D41: 10.14 | E41: 322 | F41: 36 | G41: =_xlfn.IFNA(VLOOKUP(データ!B41,[1]INVOICE!$B$33:$K$50,6,FALSE),0) -> 0 | H41: =ROUNDUP(G41/F41,0) -> 0 | I41: =G41*E41/1000 -> 0 | J41: =G41*E41/1000 -> 0 | K41: =H41*0.7 -> 0 | L41: =H41*0.7 -> 0 | M41: =L41+K41+J41 -> 0 | N41: pcs
...
