Workbook

Sheet INVOICE
A1: INVOICE
G5: インボイス作成日（Date): 5/12/2025
A8: 依頼住 (Shipper Address) | G8: Invoice No MASUDA VN-JP 019/25
A10: MASUDA VINYL VIETNAM CO.,LTD
A11: LOT NO1 DONG VANG DINH TRAM INDUSTRIAL ZONE | G11: (原産国) Country of Origin | I11: (仕向先国名) Country of Destination
A12: NENH WARD BAC NINH PROVINCE
A13: TEL : 0204 3662 777 | G13: VIETNAM | I13: JAPAN
A14: FAX : 0204 3662 825 | G14: 支払条件 (Terms of Payment)
G15: 20日締め翌月末支払 (Invoice will be closed on 20th every month and payment at end of the following month)
A16: 荷受人(Consigneer)
A19: MASUDA VINYL CO.,LTD
A20: 390ROKUGAIKECYOU KITAKU | G20: 備考 (Remark):
A21: NAGOYA CITY AICHI JAPAN
A22: TEL : 052-901-9373 | G22: P | H22: 有償（Commerical Value)
A23: FAX : 052-901-6943 | H23: 無償（No Commerical Value)
A25: Delivery to (着地) | F25: CIF | H25: 贈物（Gift)
H26: 商品見本（ Sample, No Commercial Value )
H27: その他（Other)
A30: ラベル内容 (Marks & Nos.) | B30: 内容品の記載 (Description) | D30: 注文書No PO No | E30: 単位 （Unit） | F30: 数量 （Quantity) | G30: 単価 （Unit Price） | I30: 合計 （Total Amount)
A33: 1/3 | B33: TABLE EDGE MG23 | E33: =VLOOKUP(B33,データ!$B$3:$L$85,11,FALSE) -> m | F33: 4000 | G33: =VLOOKUP(B33,データ!$B$3:$C$85,2,FALSE) -> 0.61 | I33: =IFERROR(G33*F33, "") -> 2440
A34: 1/4 | B34: PUROTEKUTA 55788-16110 | E34: =VLOOKUP(B34,データ!$B$3:$L$85,11,FALSE) -> pcs | F34: 11000 | G34: =VLOOKUP(B34,データ!$B$3:$C$85,2,FALSE) -> 0.223 | I34: =IFERROR(G34*F34, "") -> 2453
A35: 1/5 | B35: PUROTEKUTA 55788-52350 | E35: =VLOOKUP(B35,データ!$B$3:$L$85,11,FALSE) -> pcs | F35: 6000 | G35: =VLOOKUP(B35,データ!$B$3:$C$85,2,FALSE) -> 0.213 | I35: =IFERROR(G35*F35, "") -> 1278
B36: PUROTEKUTA 55788-52360 | E36: =VLOOKUP(B36,データ!$B$3:$L$85,11,FALSE) -> pcs | F36: 5000 | G36: =VLOOKUP(B36,データ!$B$3:$C$85,2,FALSE) -> 0.223 | I36: =IFERROR(G36*F36, "") -> 1115
B37: PUROTEKUTA 2A4P1-022G | E37: =VLOOKUP(B37,データ!$B$3:$L$85,11,FALSE) -> pcs | F37: 11000 | G37: =VLOOKUP(B37,データ!$B$3:$C$85,2,FALSE) -> 0.235 | I37: =IFERROR(G37*F37, "") -> 2585
B38: PUROTEKUTA 55788-K0060 | E38: =VLOOKUP(B38,データ!$B$3:$L$85,11,FALSE) -> pcs | F38: 5500 | G38: =VLOOKUP(B38,データ!$B$3:$C$85,2,FALSE) -> 0.224 | I38: =IFERROR(G38*F38, "") -> 1232
B39: PUROTEKUTA 55788-48090 | E39: =VLOOKUP(B39,データ!$B$3:$L$85,11,FALSE) -> pcs | F39: 9000 | G39: =VLOOKUP(B39,データ!$B$3:$C$85,2,FALSE) -> 0.251 | I39: =IFERROR(G39*F39, "") -> 2259
B40: PUROTEKUTA 55788-K0060 | E40: =VLOOKUP(B40,データ!$B$3:$L$85,11,FALSE) -> pcs | F40: 5500 | G40: =VLOOKUP(B40,データ!$B$3:$C$85,2,FALSE) -> 0.224 | I40: =IFERROR(G40*F40, "") -> 1232
B41: PUROTEKUTA 55788-K0060 | E41: =VLOOKUP(B41,データ!$B$3:$L$85,11,FALSE) -> pcs | F41: 13500 | G41: =VLOOKUP(B41,データ!$B$3:$C$85,2,FALSE) -> 0.224 | I41: =IFERROR(G41*F41, "") -> 3024
E42: =VLOOKUP(B42,データ!$B$3:$L$85,11,FALSE) -> #N/A | F42: 13000 | G42: =VLOOKUP(B42,データ!$B$3:$C$85,2,FALSE) -> #N/A | I42: =IFERROR(G42*F42, "")
E43: =VLOOKUP(B43,データ!$B$3:$DH$185,11,FALSE) -> #N/A | F43: 7 | G43: =VLOOKUP(B43,データ!$B$3:$C$185,2,FALSE) -> #N/A | I43: =IFERROR(G43*F43, "")
E44: =VLOOKUP(B44,データ!$B$3:$L$85,11,FALSE) -> #N/A | F44: 12000 | G44: =VLOOKUP(B44,データ!$B$3:$C$85,2,FALSE) -> #N/A | I44: =IFERROR(G44*F44, "")
B45: TABLE EDGE MI3 156 | E45: =VLOOKUP(B45,データ!$B$3:$L$85,11,FALSE) -> pcs | F45: 240 | G45: =VLOOKUP(B45,データ!$B$3:$C$85,2,FALSE) -> 2.875 | I45: =IFERROR(G45*F45, "") -> 690
A46: 合計 （Total) | I46: =SUM(I33:K45) -> 18308
A49: 原産国 (Country of Origin) : VIETNAM | G49: 署名（ Singnature )
A50: CIF TO NAGOYA PORT

Sheet PACKING LIST
A1: PACKING LIST
H5: =INVOICE!G5 -> インボイス作成日（Date): 5/12/2025
A8: 依頼住 (Shipper Address) | H8: =INVOICE!G8 -> Invoice No MASUDA VN-JP 019/25
A10: MASUDA VINYL VIETNAM CO.,LTD
A11: LOT NO1 DONG VANG DINH TRAM INDUSTRIAL ZONE | H11: (原産国) Country of Origin | J11: (仕向先国名) Country of Destination
A12: NENH WARD BAC NINH PROVINCE
A13: TEL : 0204 3662 777 | H13: VIETNAM | J13: JAPAN
A14: FAX : 0204 3662 825 | H14: 支払条件 (Terms of Payment)
H15: 20日締め翌月末支払 (Invoice will be closed on 20th every month and payment at end of the following month)
A17: 荷受人(Consigneer)
A20: MASUDA VINYL CO.,LTD | H20: 備考 (Remark):
A21: 390ROKUGAIKECYOU KITAKU
A22: NAGOYA CITY AICHI JAPAN | H22: P | I22: 有償（Commerical Value)
A23: TEL : 052-901-9373 | I23: 無償（No Commerical Value)
A24: FAX : 052-901-6943
I25: 贈物（Gift)
A26: Delivery to (着地) | G26: CIF | I26: 商品見本（ Sample, No Commercial Value )
I27: その他（Other)
A31: ラベル内容 (Marks & Nos.) | B31: 内容品の記載 (Description) | D31: 注文書No PO No | E31: 単位 （Unit） | F31: 数量 （Quantity) | G31: 梱包 （Packing） | I31: 箱数 ( Number of Boxs) | J31: パレット数 ( Number of Pallets) | K31: 総重量 (Gross weight)
A35: =IF(INVOICE!A33 <> "", INVOICE!A33, "") -> 1/3 | B35: =INVOICE!B33 -> TABLE EDGE MG23 | E35: =INVOICE!E33 -> m | F35: =INVOICE!F33 -> 4000 | I35: =IFERROR(ROUNDUP(F35/G35,0), "") | K35: =ROUND(N35+P35+20,2) -> 20
A36: =IF(INVOICE!A34 <> "", INVOICE!A34, "") -> 1/4 | B36: =INVOICE!B34 -> PUROTEKUTA 55788-16110 | E36: =INVOICE!E34 -> pcs | F36: =INVOICE!F34 -> 11000 | I36: =IFERROR(ROUNDUP(F36/G36,0), "") | K36: =ROUND(N36+P36,2)+10 -> 10
A37: =IF(INVOICE!A35 <> "", INVOICE!A35, "") -> 1/5 | B37: =INVOICE!B35 -> PUROTEKUTA 55788-52350 | E37: =INVOICE!E35 -> pcs | F37: =INVOICE!F35 -> 6000 | I37: =IFERROR(ROUNDUP(F37/G37,0), "") | K37: =ROUND(N37+P37,2)+5 -> 5
A38: =IF(INVOICE!A36 <> "", INVOICE!A36, "") | B38: =INVOICE!B36 -> PUROTEKUTA 55788-52360 | E38: =INVOICE!E36 -> pcs | F38: =INVOICE!F36 -> 5000 | I38: =IFERROR(ROUNDUP(F38/G38,0), "") | K38: =ROUND(N38+P38,2)+5 -> 5
A39: =IF(INVOICE!A37 <> "", INVOICE!A37, "") | B39: =INVOICE!B37 -> PUROTEKUTA 2A4P1-022G | E39: =INVOICE!E37 -> pcs | F39: =INVOICE!F37 -> 11000 | I39: =IFERROR(ROUNDUP(F39/G39,0), "") | K39: =ROUND(N39+P39,2)+10 -> 10
A40: =IF(INVOICE!A38 <> "", INVOICE!A38, "") | B40: =INVOICE!B38 -> PUROTEKUTA 55788-K0060 | E40: =INVOICE!E38 -> pcs | F40: =INVOICE!F38 -> 5500 | I40: =IFERROR(ROUNDUP(F40/G40,0), "") | K40: =ROUND(N40+P40,2)+10 -> 10
A41: =IF(INVOICE!A39 <> "", INVOICE!A39, "") | B41: =INVOICE!B39 -> PUROTEKUTA 55788-48090 | E41: =INVOICE!E39 -> pcs | F41: =INVOICE!F39 -> 9000 | I41: =IFERROR(ROUNDUP(F41/G41,0), "") | K41: =ROUND(N41+P41,2)+10 -> 10
A42: =IF(INVOICE!A40 <> "", INVOICE!A40, "") | B42: =INVOICE!B40 -> PUROTEKUTA 55788-K0060 | E42: =INVOICE!E40 -> pcs | F42: =INVOICE!F40 -> 5500 | I42: =IFERROR(ROUNDUP(F42/G42,0), "") | K42: =ROUND(N42+P42,2)+10 -> 10
A43: =IF(INVOICE!A41 <> "", INVOICE!A41, "") | B43: =INVOICE!B41 -> PUROTEKUTA 55788-K0060 | E43: =INVOICE!E41 -> pcs | F43: =INVOICE!F41 -> 13500 | I43: =IFERROR(ROUNDUP(F43/G43,0), "") | K43: =ROUND(N43+P43,2)+20 -> 20
A44: =IF(INVOICE!A42 <> "", INVOICE!A42, "") | B44: =INVOICE!B42 -> 0 | E44: =INVOICE!E42 -> #N/A | F44: =INVOICE!F42 -> 13000 | I44: =IFERROR(ROUNDUP(F44/G44,0), "") | K44: =ROUND(N44+P44,2)+20 -> 20
A45: =IF(INVOICE!A43 <> "", INVOICE!A43, "") | B45: =INVOICE!B43 -> 0 | E45: =INVOICE!E43 -> #N/A | F45: =INVOICE!F43 -> 7 | I45: =IFERROR(ROUNDUP(F45/G45,0), "") | K45: =ROUND(N45+P45,2) -> 0
A46: =IF(INVOICE!A44 <> "", INVOICE!A44, "") | B46: =INVOICE!B44 -> 0 | E46: =INVOICE!E44 -> #N/A | F46: =INVOICE!F44 -> 12000 | I46: =IFERROR(ROUNDUP(F46/G46,0), "") | K46: =ROUND(N46+P46,2)+100 -> 100
A47: =IF(INVOICE!A45 <> "", INVOICE!A45, "") | B47: =INVOICE!B45 -> TABLE EDGE MI3 156 | E47: =INVOICE!E45 -> pcs | F47: =INVOICE!F45 -> 240 | I47: =IFERROR(ROUNDUP(F47/G47,0), "") | K47: =ROUND(N47+P47,2)+20 -> 20
A49: 合計 （Total) | F49: =SUMIF(E35:E48,L42,F35:F48) -> 0 | I49: =SUMIF(E35:E48,L42,I35:I48)+SUMIF(E35:E48,L44,I35:I48) -> 0 | J49: =SUM(J35:J48) -> 0 | K49: =SUM(K35:K48) -> 240
F51: =SUMIF(E35:E48,L43,F35:F48) -> 0 | I51: =SUMIF(E35:E48,L43,I35:I48) -> 0
F52: =SUMIF(E35:E48,L44,F35:F48) -> 0
A53: =INVOICE!A50 -> CIF TO NAGOYA PORT
A54: 郵便物の個数 ( Number of pieces, m) : | D54: =F49 -> 0 | E54: =F51 -> 0 | F54: =F52 -> 0 | I54: 署名（ Singnature )
A55: 総重量（Gross weight) Kg : | D55: =K49 -> 240 | E55: =J49 -> 0
A56: 原産国（Country of Origin) :VIETNAM | D56: =1.1*1.5*1.1*6+1.1*1.1*1.4+1.1*1.2*1.8*5+1.1*1.1*1 -> 25.674
A57: 輸送方法 ( Shipped per) : SEA

Sheet INVOICE-20
A1: INVOICE
G5: インボイス作成日（Date): 5/12/2025
A8: 依頼住 (Shipper Address) | G8: Invoice No MASUDA VN-JP 019/25
A10: MASUDA VINYL VIETNAM CO.,LTD
A11: LOT NO1 DONG VANG DINH TRAM INDUSTRIAL ZONE | G11: (原産国) Country of Origin | I11: (仕向先国名) Country of Destination
A12: NENH WARD BAC NINH PROVINCE
A13: TEL : 0204 3662 777 | G13: VIETNAM | I13: JAPAN
A14: FAX : 0204 3662 825 | G14: 支払条件 (Terms of Payment)
G15: 20日締め翌月末支払 (Invoice will be closed on 20th every month and payment at end of the following month)
A16: 荷受人(Consigneer)
A19: MASUDA VINYL CO.,LTD
A20: 390ROKUGAIKECYOU KITAKU | G20: 備考 (Remark):
A21: NAGOYA CITY AICHI JAPAN
A22: TEL : 052-901-9373 | G22: P | H22: 有償（Commerical Value)
A23: FAX : 052-901-6943 | H23: 無償（No Commerical Value)
A25: Delivery to (着地) | F25: CIF | H25: 贈物（Gift)
H26: 商品見本（ Sample, No Commercial Value )
H27: その他（Other)
A30: ラベル内容 (Marks & Nos.) | B30: 内容品の記載 (Description) | D30: 注文書No PO No | E30: 単位 （Unit） | F30: 数量 （Quantity) | G30: 単価 （Unit Price） | I30: 合計 （Total Amount)
B33: TABLE EDGE MG23 | E33: =VLOOKUP(B33,データ!$B$3:$L$85,11,FALSE) -> m | F33: 4000 | G33: =VLOOKUP(B33,データ!$B$3:$C$85,2,FALSE) -> 0.61 | I33: =IFERROR(G33*F33, "") -> 2440
B34: PUROTEKUTA 55788-16110 | E34: =VLOOKUP(B34,データ!$B$3:$L$85,11,FALSE) -> pcs | F34: 11000 | G34: =VLOOKUP(B34,データ!$B$3:$C$85,2,FALSE) -> 0.223 | I34: =IFERROR(G34*F34, "") -> 2453
B35: PUROTEKUTA 55788-52350 | E35: =VLOOKUP(B35,データ!$B$3:$L$85,11,FALSE) -> pcs | F35: 6000 | G35: =VLOOKUP(B35,データ!$B$3:$C$85,2,FALSE) -> 0.213 | I35: =IFERROR(G35*F35, "") -> 1278
B36: PUROTEKUTA 55788-52360 | E36: =VLOOKUP(B36,データ!$B$3:$L$85,11,FALSE) -> pcs | F36: 5000 | G36: =VLOOKUP(B36,データ!$B$3:$C$85,2,FALSE) -> 0.223 | I36: =IFERROR(G36*F36, "") -> 1115
B37: PUROTEKUTA 2A4P1-022G | E37: =VLOOKUP(B37,データ!$B$3:$L$85,11,FALSE) -> pcs | F37: 11000 | G37: =VLOOKUP(B37,データ!$B$3:$C$85,2,FALSE) -> 0.235 | I37: =IFERROR(G37*F37, "") -> 2585
B38: PUROTEKUTA 55788-K0060 | E38: =VLOOKUP(B38,データ!$B$3:$L$85,11,FALSE) -> pcs | F38: 5500 | G38: =VLOOKUP(B38,データ!$B$3:$C$85,2,FALSE) -> 0.224 | I38: =IFERROR(G38*F38, "") -> 1232
B39: PUROTEKUTA 55788-48090 | E39: =VLOOKUP(B39,データ!$B$3:$L$85,11,FALSE) -> pcs | F39: 9000 | G39: =VLOOKUP(B39,データ!$B$3:$C$85,2,FALSE) -> 0.251 | I39: =IFERROR(G39*F39, "") -> 2259
B40: PUROTEKUTA 55788-K0060 | E40: =VLOOKUP(B40,データ!$B$3:$L$85,11,FALSE) -> pcs | F40: 5500 | G40: =VLOOKUP(B40,データ!$B$3:$C$85,2,FALSE) -> 0.224 | I40: =IFERROR(G40*F40, "") -> 1232
B41: PUROTEKUTA 55788-K0060 | E41: =VLOOKUP(B41,データ!$B$3:$L$85,11,FALSE) -> pcs | F41: 13500 | G41: =VLOOKUP(B41,データ!$B$3:$C$85,2,FALSE) -> 0.224 | I41: =IFERROR(G41*F41, "") -> 3024
E42: =VLOOKUP(B42,データ!$B$3:$L$85,11,FALSE) -> #N/A | F42: 13000 | G42: =VLOOKUP(B42,データ!$B$3:$C$85,2,FALSE) -> #N/A | I42: =IFERROR(G42*F42, "")
E43: =VLOOKUP(B43,データ!$B$3:$DH$185,11,FALSE) -> #N/A | F43: 7 | G43: =VLOOKUP(B43,データ!$B$3:$C$185,2,FALSE) -> #N/A | I43: =IFERROR(G43*F43, "")
E44: =VLOOKUP(B44,データ!$B$3:$L$85,11,FALSE) -> #N/A | F44: 12000 | G44: =VLOOKUP(B44,データ!$B$3:$C$85,2,FALSE) -> #N/A | I44: =IFERROR(G44*F44, "")
E45: =VLOOKUP(B45,データ!$B$3:$L$85,11,FALSE) -> #N/A | F45: 240 | G45: =VLOOKUP(B45,データ!$B$3:$C$85,2,FALSE) -> #N/A | I45: =IFERROR(G45*F45, "")
E46: =VLOOKUP(B46,データ!$B$3:$L$85,11,FALSE) -> #N/A | F46: 13000 | G46: =VLOOKUP(B46,データ!$B$3:$C$85,2,FALSE) -> #N/A | I46: =IFERROR(G46*F46, "")
E47: =VLOOKUP(B47,データ!$B$3:$DH$185,11,FALSE) -> #N/A | F47: 7 | G47: =VLOOKUP(B47,データ!$B$3:$C$185,2,FALSE) -> #N/A | I47: =IFERROR(G47*F47, "")
E48: =VLOOKUP(B48,データ!$B$3:$L$85,11,FALSE) -> #N/A | F48: 12000 | G48: =VLOOKUP(B48,データ!$B$3:$C$85,2,FALSE) -> #N/A | I48: =IFERROR(G48*F48, "")
E49: =VLOOKUP(B49,データ!$B$3:$L$85,11,FALSE) -> #N/A | F49: 13000 | G49: =VLOOKUP(B49,データ!$B$3:$C$85,2,FALSE) -> #N/A | I49: =IFERROR(G49*F49, "")
E50: =VLOOKUP(B50,データ!$B$3:$DH$185,11,FALSE) -> #N/A | F50: 7 | G50: =VLOOKUP(B50,データ!$B$3:$C$185,2,FALSE) -> #N/A | I50: =IFERROR(G50*F50, "")
E51: =VLOOKUP(B51,データ!$B$3:$L$85,11,FALSE) -> #N/A | F51: 12000 | G51: =VLOOKUP(B51,データ!$B$3:$C$85,2,FALSE) -> #N/A | I51: =IFERROR(G51*F51, "")
E52: =VLOOKUP(B52,データ!$B$3:$L$85,11,FALSE) -> #N/A | F52: 240 | G52: =VLOOKUP(B52,データ!$B$3:$C$85,2,FALSE) -> #N/A | I52: =IFERROR(G52*F52, "")
A53: 合計 （Total) | I53: =SUM(I33:K52) -> 17618
...

Sheet PACKING LIST-20
A1: PACKING LIST
H5: =INVOICE!G5 -> インボイス作成日（Date): 5/12/2025
A8: 依頼住 (Shipper Address) | H8: =INVOICE!G8 -> Invoice No MASUDA VN-JP 019/25
A10: MASUDA VINYL VIETNAM CO.,LTD
A11: LOT NO1 DONG VANG DINH TRAM INDUSTRIAL ZONE | H11: (原産国) Country of Origin | J11: (仕向先国名) Country of Destination
A12: NENH WARD BAC NINH PROVINCE
A13: TEL : 0204 3662 777 | H13: VIETNAM | J13: JAPAN
A14: FAX : 0204 3662 825 | H14: 支払条件 (Terms of Payment)
H15: 20日締め翌月末支払 (Invoice will be closed on 20th every month and payment at end of the following month)
A17: 荷受人(Consigneer)
A20: MASUDA VINYL CO.,LTD | H20: 備考 (Remark):
A21: 390ROKUGAIKECYOU KITAKU
A22: NAGOYA CITY AICHI JAPAN | H22: P | I22: 有償（Commerical Value)
A23: TEL : 052-901-9373 | I23: 無償（No Commerical Value)
A24: FAX : 052-901-6943
I25: 贈物（Gift)
A26: Delivery to (着地) | G26: CIF | I26: 商品見本（ Sample, No Commercial Value )
I27: その他（Other)
A31: ラベル内容 (Marks & Nos.) | B31: 内容品の記載 (Description) | D31: 注文書No PO No | E31: 単位 （Unit） | F31: 数量 （Quantity) | G31: 梱包 （Packing） | I31: 箱数 ( Number of Boxs) | J31: パレット数 ( Number of Pallets) | K31: 総重量 (Gross weight)
A35: =IF('INVOICE-20'!A33 <> "", 'INVOICE-20'!A33, "") | B35: ='INVOICE-20'!B33 -> TABLE EDGE MG23 | E35: ='INVOICE-20'!E33 -> m | F35: ='INVOICE-20'!F33 -> 4000 | I35: =IFERROR(ROUNDUP(F35/G35,0), "") | K35: =ROUND(N35+P35+20,2) -> 20
A36: =IF('INVOICE-20'!A34 <> "", 'INVOICE-20'!A34, "") | B36: ='INVOICE-20'!B34 -> PUROTEKUTA 55788-16110 | E36: ='INVOICE-20'!E34 -> pcs | F36: ='INVOICE-20'!F34 -> 11000 | I36: =IFERROR(ROUNDUP(F36/G36,0), "") | K36: =ROUND(N36+P36,2)+10 -> 10
A37: =IF('INVOICE-20'!A35 <> "", 'INVOICE-20'!A35, "") | B37: ='INVOICE-20'!B35 -> PUROTEKUTA 55788-52350 | E37: ='INVOICE-20'!E35 -> pcs | F37: ='INVOICE-20'!F35 -> 6000 | I37: =IFERROR(ROUNDUP(F37/G37,0), "") | K37: =ROUND(N37+P37,2)+5 -> 5
A38: =IF('INVOICE-20'!A36 <> "", 'INVOICE-20'!A36, "") | B38: ='INVOICE-20'!B36 -> PUROTEKUTA 55788-52360 | E38: ='INVOICE-20'!E36 -> pcs | F38: ='INVOICE-20'!F36 -> 5000 | I38: =IFERROR(ROUNDUP(F38/G38,0), "") | K38: =ROUND(N38+P38,2)+5 -> 5
A39: =IF('INVOICE-20'!A37 <> "", 'INVOICE-20'!A37, "") | B39: ='INVOICE-20'!B37 -> PUROTEKUTA 2A4P1-022G | E39: ='INVOICE-20'!E37 -> pcs | F39: ='INVOICE-20'!F37 -> 11000 | I39: =IFERROR(ROUNDUP(F39/G39,0), "") | K39: =ROUND(N39+P39,2)+10 -> 10
A40: =IF('INVOICE-20'!A38 <> "", 'INVOICE-20'!A38, "") | B40: ='INVOICE-20'!B38 -> PUROTEKUTA 55788-K0060 | E40: ='INVOICE-20'!E38 -> pcs | F40: ='INVOICE-20'!F38 -> 5500 | I40: =IFERROR(ROUNDUP(F40/G40,0), "") | K40: =ROUND(N40+P40,2)+10 -> 10
A41: =IF('INVOICE-20'!A39 <> "", 'INVOICE-20'!A39, "") | B41: ='INVOICE-20'!B39 -> PUROTEKUTA 55788-48090 | E41: ='INVOICE-20'!E39 -> pcs | F41: ='INVOICE-20'!F39 -> 9000 | I41: =IFERROR(ROUNDUP(F41/G41,0), "") | K41: =ROUND(N41+P41,2)+10 -> 10
A42: =IF('INVOICE-20'!A40 <> "", 'INVOICE-20'!A40, "") | B42: ='INVOICE-20'!B40 -> PUROTEKUTA 55788-K0060 | E42: ='INVOICE-20'!E40 -> pcs | F42: ='INVOICE-20'!F40 -> 5500 | I42: =IFERROR(ROUNDUP(F42/G42,0), "") | K42: =ROUND(N42+P42,2)+10 -> 10
A43: =IF('INVOICE-20'!A41 <> "", 'INVOICE-20'!A41, "") | B43: ='INVOICE-20'!B41 -> PUROTEKUTA 55788-K0060 | E43: ='INVOICE-20'!E41 -> pcs | F43: ='INVOICE-20'!F41 -> 13500 | I43: =IFERROR(ROUNDUP(F43/G43,0), "") | K43: =ROUND(N43+P43,2)+10 -> 10
A44: =IF('INVOICE-20'!A42 <> "", 'INVOICE-20'!A42, "") | B44: ='INVOICE-20'!B42 -> 0 | E44: ='INVOICE-20'!E42 -> #N/A | F44: ='INVOICE-20'!F42 -> 13000 | I44: =IFERROR(ROUNDUP(F44/G44,0), "") | K44: =ROUND(N44+P44,2)+10 -> 10
A45: =IF('INVOICE-20'!A43 <> "", 'INVOICE-20'!A43, "") | B45: ='INVOICE-20'!B43 -> 0 | E45: ='INVOICE-20'!E43 -> #N/A | F45: ='INVOICE-20'!F43 -> 7 | I45: =IFERROR(ROUNDUP(F45/G45,0), "") | K45: =ROUND(N45+P45,2)+10 -> 10
A46: =IF('INVOICE-20'!A44 <> "", 'INVOICE-20'!A44, "") | B46: ='INVOICE-20'!B44 -> 0 | E46: ='INVOICE-20'!E44 -> #N/A | F46: ='INVOICE-20'!F44 -> 12000 | I46: =IFERROR(ROUNDUP(F46/G46,0), "") | K46: =ROUND(N46+P46,2)+10 -> 10
A47: =IF('INVOICE-20'!A45 <> "", 'INVOICE-20'!A45, "") | B47: ='INVOICE-20'!B45 -> 0 | E47: ='INVOICE-20'!E45 -> #N/A | F47: ='INVOICE-20'!F45 -> 240 | I47: =IFERROR(ROUNDUP(F47/G47,0), "") | K47: =ROUND(N47+P47,2)+10 -> 10
A48: =IF('INVOICE-20'!A46 <> "", 'INVOICE-20'!A46, "") | B48: ='INVOICE-20'!B46 -> 0 | E48: ='INVOICE-20'!E46 -> #N/A | F48: ='INVOICE-20'!F46 -> 13000 | I48: =IFERROR(ROUNDUP(F48/G48,0), "") | K48: =ROUND(N48+P48,2)+10 -> 10
A49: =IF('INVOICE-20'!A47 <> "", 'INVOICE-20'!A47, "") | B49: ='INVOICE-20'!B47 -> 0 | E49: ='INVOICE-20'!E47 -> #N/A | F49: ='INVOICE-20'!F47 -> 7 | I49: =IFERROR(ROUNDUP(F49/G49,0), "") | K49: =ROUND(N49+P49,2)+10 -> 10
A50: =IF('INVOICE-20'!A48 <> "", 'INVOICE-20'!A48, "") | B50: ='INVOICE-20'!B48 -> 0 | E50: ='INVOICE-20'!E48 -> #N/A | F50: ='INVOICE-20'!F48 -> 12000 | I50: =IFERROR(ROUNDUP(F50/G50,0), "") | K50: =ROUND(N50+P50,2)+10 -> 10
... A54: =IF('INVOICE-20'!A52 <> "", 'INVOICE-20'!A52, "") | B54: ='INVOICE-20'!B52 -> 0 | E54: ='INVOICE-20'!E52 -> #N/A | F54: ='INVOICE-20'!F52 -> 240 | I54: =IFERROR(ROUNDUP(F54/G54,0), "") | K54: =ROUND(N54+P54,2)+10 -> 10
A55: 合計 （Total) | F55: =SUMIF(E35:E54,L42,F35:F54) -> 0 | I55: =SUMIF(E35:E54,L42,I35:I54)+SUMIF(E35:E54,L44,I35:I54) -> 0 | J55: =SUM(J35:J54) -> 0 | K55: =SUM(K35:K54) -> 200
F57: =SUMIF(E35:E54,L43,F35:F54) -> 0 | I57: =SUMIF(E35:E54,L43,I35:I54) -> 0
F58: =SUMIF(E35:E54,L44,F35:F54) -> 0
A59: ='INVOICE-20'!A57 -> CIF TO NAGOYA PORT
...

Sheet データ
A2: No | B2: 品名 | C2: 単価 | D2: 重さ | E2: 梱包 | F2: 出荷数 | G2: 箱数 | H2: 使用材 | I2: 袋 | J2: 段ボール | K2: 総数量 | L2: 単位 | M2: Mã HS code | N2: SL2
A3: 1 | B3: MASUGOMU 4140 | C3: 0.78 | D3: 100 | E3: 180 | F3: =_xlfn.IFNA(VLOOKUP(B3,'PACKING LIST'!$B$35:$F$54,5,FALSE),0) -> 0 | G3: =ROUNDUP(F3/E3,0) -> 0 | H3: =F3*D3/1000 -> 0 | I3: =G3*6*0.4/1000 -> 0 | J3: =G3*0.7 -> 0 | K3: =J3+I3+H3 -> 0 | L3: pcs | M3: 39161020 | N3: Kg
A4: =A3+1 -> 2 | B4: MASUGOMU 4080 | C4: =0.44 -> 0.44 | D4: 53 | E4: 350 | F4: =_xlfn.IFNA(VLOOKUP(B4,'PACKING LIST'!$B$35:$F$54,5,FALSE),0) -> 0 | G4: =ROUNDUP(F4/E4,0) -> 0 | H4: =F4*D4/1000 -> 0 | I4: =G4*7*0.4/1000 -> 0 | J4: =G4*0.7 -> 0 | K4: =J4+I4+H4 -> 0 | L4: pcs | M4: 39161020 | N4: Kg
A5: 3 | B5: MASUGOMU 4090 | C5: 0.49 | D5: 60 | E5: 360 | F5: =_xlfn.IFNA(VLOOKUP(B5,'PACKING LIST'!$B$35:$F$54,5,FALSE),0) -> 0 | G5: =ROUNDUP(F5/E5,0) -> 0 | H5: =F5*D5/1000 -> 0 | I5: =G5*7*0.4/1000 -> 0 | J5: =G5*0.7 -> 0 | K5: =J5+I5+H5 -> 0 | L5: pcs | M5: 39161020 | N5: Kg
A6: =A5+1 -> 4 | B6: MASUGOMU 4120 | C6: =0.38 -> 0.38 | D6: 43 | E6: 360 | F6: =_xlfn.IFNA(VLOOKUP(B6,'PACKING LIST'!$B$35:$F$54,5,FALSE),0) -> 0 | G6: =ROUNDUP(F6/E6,0) -> 0 | H6: =F6*D6/1000 -> 0 | I6: =G6*7*0.4/1000 -> 0 | J6: =G6*0.7 -> 0 | K6: =J6+I6+H6 -> 0 | L6: pcs | M6: 39161020 | N6: Kg
A7: =A6+1 -> 5 | B7: MASUGOMU 4130 | C7: =0.25 -> 0.25 | D7: 28 | E7: 540 | F7: =_xlfn.IFNA(VLOOKUP(B7,'PACKING LIST'!$B$35:$F$54,5,FALSE),0) -> 0 | G7: =ROUNDUP(F7/E7,0) -> 0 | H7: =F7*D7/1000 -> 0 | I7: =G7*7*0.4/1000 -> 0 | J7: =G7*0.7 -> 0 | K7: =J7+I7+H7 -> 0 | L7: pcs | M7: 39161020 | N7: Kg
A8: =A7+1 -> 6 | B8: MASUGOMU 4240 | C8: =0.38 -> 0.38 | D8: 43 | E8: 360 | F8: =_xlfn.IFNA(VLOOKUP(B8,'PACKING LIST'!$B$35:$F$54,5,FALSE),0) -> 0 | G8: =ROUNDUP(F8/E8,0) -> 0 | H8: =F8*D8/1000 -> 0 | I8: =G8*7*0.4/1000 -> 0 | J8: =G8*0.7 -> 0 | K8: =J8+I8+H8 -> 0 | L8: pcs | M8: 39161020 | N8: Kg
A9: =A8+1 -> 7 | B9: TABLE EDGE MG23 | C9: 0.61 | D9: =3.9/50*1000 -> 78 | E9: 50 | F9: =_xlfn.IFNA(VLOOKUP(B9,'PACKING LIST'!$B$35:$F$54,5,FALSE),0) -> 4000 | G9: =ROUNDUP(F9/E9,0) -> 80 | H9: =G9*D9 -> 6240 | J9: =G9*0 -> 0 | K9: =J9+I9+H9 -> 6240 | L9: m | M9: 39169092 | N9: Kg
A10: =A9+1 -> 8 | B10: KATEKUSU 2.5ø 73L | C10: 0.011 | D10: 0.7 | E10: 20000 | F10: =_xlfn.IFNA(VLOOKUP(B10,'PACKING LIST'!$B$35:$F$54,5,FALSE),0) -> 0 | G10: =ROUNDUP(F10/E10,0) -> 0 | H10: =F10*D10/1000 -> 0 | J10: =G10*0.7 -> 0 | K10: =J10+I10+H10 -> 0 | L10: pcs | M10: 39169092 | N10: Kg
A11: =A10+1 -> 9 | B11: KATEKUSU 2.5ø 50L | C11: 0.01 | D11: 0.7 | E11: 20000 | F11: =_xlfn.IFNA(VLOOKUP(B11,'PACKING LIST'!$B$35:$F$54,5,FALSE),0) -> 0 | G11: =ROUNDUP(F11/E11,0) -> 0 | H11: =F11*D11/1000 -> 0 | J11: =G11*0.7 -> 0 | K11: =J11+I11+H11 -> 0 | L11: pcs | M11: 39169092 | N11: Kg
A12: =A10+1 -> 9 | B12: KATEKUSU 2.5ø 95L | C12: 0.013 | D12: 0.7 | E12: 20000 | F12: =_xlfn.IFNA(VLOOKUP(B12,'PACKING LIST'!$B$35:$F$54,5,FALSE),0) -> 0 | G12: =ROUNDUP(F12/E12,0) -> 0 | H12: =F12*D12/1000 -> 0 | J12: =G12*0.7 -> 0 | K12: =J12+I12+H12 -> 0 | L12: pcs | M12: 39169092 | N12: Kg
A13: =A10+1 -> 9 | B13: KATEKUSU 2.5ø 100L | C13: 0.013 | D13: 0.8 | E13: 20000 | F13: =_xlfn.IFNA(VLOOKUP(B13,'PACKING LIST'!$B$35:$F$54,5,FALSE),0) -> 0 | G13: =ROUNDUP(F13/E13,0) -> 0 | H13: =F13*D13/1000 -> 0 | J13: =G13*0.7 -> 0 | K13: =J13+I13+H13 -> 0 | L13: pcs | M13: 39169092 | N13: Kg
A14: =A12+1 -> 10 | B14: KATEKUSU 2.5ø 135L | C14: 0.015 | D14: 0.8 | E14: 20000 | F14: =_xlfn.IFNA(VLOOKUP(B14,'PACKING LIST'!$B$35:$F$54,5,FALSE),0) -> 0 | G14: =ROUNDUP(F14/E14,0) -> 0 | H14: =F14*D14/1000 -> 0 | J14: =G14*0.7 -> 0 | K14: =J14+I14+H14 -> 0 | L14: pcs | M14: 39169092 | N14: Kg
B15: KATEKUSU 3ø 30L | C15: 0.01 | D15: 0.8 | E15: 20000 | F15: =_xlfn.IFNA(VLOOKUP(B15,'PACKING LIST'!$B$35:$F$54,5,FALSE),0) -> 0 | G15: =ROUNDUP(F15/E15,0) -> 0 | H15: =F15*D15/1000 -> 0 | J15: =G15*0.7 -> 0 | K15: =J15+I15+H15 -> 0 | L15: pcs | M15: 39169092 | N15: Kg
B16: KATEKUSU 3ø 40L | C16: 0.01 | D16: 0.8 | E16: 20000 | F16: =_xlfn.IFNA(VLOOKUP(B16,'PACKING LIST'!$B$35:$F$54,5,FALSE),0) -> 0 | G16: =ROUNDUP(F16/E16,0) -> 0 | H16: =F16*D16/1000 -> 0 | J16: =G16*0.7 -> 0 | K16: =J16+I16+H16 -> 0 | L16: pcs | M16: 39169092 | N16: Kg
B17: KATEKUSU 3ø 45L | C17: 0.01 | D17: 0.8 | E17: 20000 | F17: =_xlfn.IFNA(VLOOKUP(B17,'PACKING LIST'!$B$35:$F$54,5,FALSE),0) -> 0 | G17: =ROUNDUP(F17/E17,0) -> 0 | H17: =F17*D17/1000 -> 0 | J17: =G17*0.7 -> 0 | K17: =J17+I17+H17 -> 0 | L17: pcs | M17: 39169092 | N17: Kg
B18: KATEKUSU 3ø 90L | C18: 0.013 | D18: 0.8 | E18: 20000 | F18: =_xlfn.IFNA(VLOOKUP(B18,'PACKING LIST'!$B$35:$F$54,5,FALSE),0) -> 0 | G18: =ROUNDUP(F18/E18,0) -> 0 | H18: =F18*D18/1000 -> 0 | J18: =G18*0.7 -> 0 | K18: =J18+I18+H18 -> 0 | L18: pcs | M18: 39169092 | N18: Kg
A19: =A13+1 -> 10 | B19: KATEKUSU 3ø 100L | C19: 0.013 | D19: 0.8 | E19: 20000 | F19: =_xlfn.IFNA(VLOOKUP(B19,'PACKING LIST'!$B$35:$F$54,5,FALSE),0) -> 0 | G19: =ROUNDUP(F19/E19,0) -> 0 | H19: =F19*D19/1000 -> 0 | J19: =G19*0.7 -> 0 | K19: =J19+I19+H19 -> 0 | L19: pcs | M19: 39169092 | N19: Kg
A20: =A19+1 -> 11 | B20: KATEKUSU 3ø 150L | C20: 0.013 | D20: 1.1 | E20: 10000 | F20: =_xlfn.IFNA(VLOOKUP(B20,'PACKING LIST'!$B$35:$F$54,5,FALSE),0) -> 0 | G20: =ROUNDUP(F20/E20,0) -> 0 | H20: =F20*D20/1000 -> 0 | J20: =G20*0.7 -> 0 | K20: =J20+I20+H20 -> 0 | L20: pcs | M20: 39169092 | N20: Kg
A21: =A19+1 -> 11 | B21: KATEKUSU 4ø 50L | C21: 0.013 | D21: 1.1 | E21: 10000 | F21: =_xlfn.IFNA(VLOOKUP(B21,'PACKING LIST'!$B$35:$F$54,5,FALSE),0) -> 0 | G21: =ROUNDUP(F21/E21,0) -> 0 | H21: =F21*D21/1000 -> 0 | J21: =G21*0.7 -> 0 | K21: =J21+I21+H21 -> 0 | L21: pcs | M21: 39169092 | N21: Kg
A22: =A20+1 -> 12 | B22: KATEKUSU 4ø 100L | C22: 0.016 | D22: 1.1 | E22: 10000 | F22: =_xlfn.IFNA(VLOOKUP(B22,'PACKING LIST'!$B$35:$F$54,5,FALSE),0) -> 0 | G22: =ROUNDUP(F22/E22,0) -> 0 | H22: =F22*D22/1000 -> 0 | J22: =G22*0.7 -> 0 | K22: =J22+I22+H22 -> 0 | L22: pcs | M22: 39169092 | N22: Kg
A23: =A22+1 -> 13 | B23: KATEKUSU 5ø 183L | C23: 0.053 | D23: 3.7 | E23: 5000 | F23: =_xlfn.IFNA(VLOOKUP(B23,'PACKING LIST'!$B$35:$F$54,5,FALSE),0) -> 0 | G23: =ROUNDUP(F23/E23,0) -> 0 | H23: =F23*D23/1000 -> 0 | J23: =G23*0.7 -> 0 | K23: =J23+I23+H23 -> 0 | L23: pcs | M23: 39169092 | N23: Kg
A24: =A23+1 -> 14 | B24: SHEET JOINT 100L | C24: 0.037 | D24: 4.3 | E24: 3000 | F24: =_xlfn.IFNA(VLOOKUP(B24,'PACKING LIST'!$B$35:$F$54,5,FALSE),0) -> 0 | G24: =ROUNDUP(F24/E24,0) -> 0 | H24: =F24*D24/1000 -> 0 | J24: =G24*0.7 -> 0 | K24: =J24+I24+H24 -> 0 | L24: pcs | M24: 39269049 | N24: PCE
A25: =A24+1 -> 15 | B25: SHEET JOINT 150L | C25: 0.05 | D25: 5.5 | E25: 1500 | F25: =_xlfn.IFNA(VLOOKUP(B25,'PACKING LIST'!$B$35:$F$54,5,FALSE),0) -> 0 | G25: =ROUNDUP(F25/E25,0) -> 0 | H25: =F25*D25/1000 -> 0 | J25: =G25*0.7 -> 0 | K25: =J25+I25+H25 -> 0 | L25: pcs | M25: 39269049 | N25: PCE
A26: =A25+1 -> 16 | B26: SHEET JOINT 200L | C26: 0.07 | D26: 7.2 | E26: 1500 | F26: =_xlfn.IFNA(VLOOKUP(B26,'PACKING LIST'!$B$35:$F$54,5,FALSE),0) -> 0 | G26: =ROUNDUP(F26/E26,0) -> 0 | H26: =F26*D26/1000 -> 0 | J26: =G26*0.7 -> 0 | K26: =J26+I26+H26 -> 0 | L26: pcs | M26: 39269049 | N26: PCE
A27: =A26+1 -> 17 | B27: SHEET JOINT 290L | C27: 0.08 | D27: 12.4 | E27: 1000 | F27: =_xlfn.IFNA(VLOOKUP(B27,'PACKING LIST'!$B$35:$F$54,5,FALSE),0) -> 0 | G27: =ROUNDUP(F27/E27,0) -> 0 | H27: =F27*D27/1000 -> 0 | J27: =G27*0.7 -> 0 | K27: =J27+I27+H27 -> 0 | L27: pcs | M27: 39269049 | N27: PCE
A28: =A27+1 -> 18 | B28: TABLE EDGE MI3 | C28: 0.587 | D28: 8.4 | E28: 50 | F28: =_xlfn.IFNA(VLOOKUP(B28,'PACKING LIST'!$B$35:$F$54,5,FALSE),0) -> 0 | G28: =ROUNDUP(F28/E28,0) -> 0 | H28: =F28*D28 -> 0 | J28: =G28*0 -> 0 | K28: =J28+I28+H28 -> 0 | L28: m | M28: 39169092 | N28: Kg
A29: =A28+1 -> 19 | B29: TABLE EDGE MI3 156 | C29: 2.875 | D29: =4140*167/1000 -> 691.38 | E29: 30 | F29: =_xlfn.IFNA(VLOOKUP(B29,'PACKING LIST'!$B$35:$F$54,5,FALSE),0) -> 240 | G29: =ROUNDUP(F29/E29,0) -> 8 | H29: =F29*D29 -> 165931.2 | J29: =G29*1 -> 8 | K29: =J29+I29+H29 -> 165939.2 | L29: pcs | M29: 39169092 | N29: Kg
A30: =A29+1 -> 20 | B30: TABLE EDGE MI3 26 | C30: 3.017 | D30: =4416*167/1000 -> 737.472 | E30: 30 | F30: =_xlfn.IFNA(VLOOKUP(B30,'PACKING LIST'!$B$35:$F$54,5,FALSE),0) -> 0 | G30: =ROUNDUP(F30/E30,0) -> 0 | H30: =F30*D30 -> 0 | J30: =G30*1 -> 0 | K30: =J30+I30+H30 -> 0 | L30: pcs | M30: 39169092 | N30: Kg
A31: =A30+1 -> 21 | B31: TABLE EDGE MI3 256 | C31: 3.229 | D31: =0.77*1000 -> 770 | E31: 30 | F31: =_xlfn.IFNA(VLOOKUP(B31,'PACKING LIST'!$B$35:$F$54,5,FALSE),0) -> 0 | G31: =ROUNDUP(F31/E31,0) -> 0 | H31: =F31*D31 -> 0 | J31: =G31*1 -> 0 | K31: =J31+I31+H31 -> 0 | L31: pcs | M31: 39169092 | N31: Kg
A32: =A31+1 -> 22 | B32: TABLE EDGE MI3 36 | C32: 3.158 | D32: =0.84*1000 -> 840 | E32: 30 | F32: =_xlfn.IFNA(VLOOKUP(B32,'PACKING LIST'!$B$35:$F$54,5,FALSE),0) -> 0 | G32: =ROUNDUP(F32/E32,0) -> 0 | H32: =F32*D32 -> 0 | J32: =G32*1 -> 0 | K32: =J32+I32+H32 -> 0 | L32: pcs | M32: 39169092 | N32: Kg
A33: =A32+1 -> 23 | B33: TABLE EDGE MI3 155 | C33: 2.509 | D33: =0.624*1000 -> 624 | E33: 30 | F33: =_xlfn.IFNA(VLOOKUP(B33,'PACKING LIST'!$B$35:$F$54,5,FALSE),0) -> 0 | G33: =ROUNDUP(F33/E33,0) -> 0 | H33: =F33*D33 -> 0 | J33: =G33*1 -> 0 | K33: =J33+I33+H33 -> 0 | L33: pcs | M33: 39169092 | N33: Kg
A34: =A33+1 -> 24 | B34: TABLE EDGE MI3 25 | C34: 2.698 | D34: =0.673*1000 -> 673 | E34: 30 | F34: =_xlfn.IFNA(VLOOKUP(B34,'PACKING LIST'!$B$35:$F$54,5,FALSE),0) -> 0 | G34: =ROUNDUP(F34/E34,0) -> 0 | H34: =F34*D34 -> 0 | J34: =G34*1 -> 0 | K34: =J34+I34+H34 -> 0 | L34: pcs | M34: 39169092 | N34: Kg
A35: =A34+1 -> 25 | B35: PUROTEKUTA 55788-02270 | C35: 0.2046 | D35: 21.6 | E35: 500 | F35: =_xlfn.IFNA(VLOOKUP(B35,'PACKING LIST'!$B$35:$F$54,5,FALSE),0) -> 0 | G35: =ROUNDUP(F35/E35,0) -> 0 | H35: =F35*D35/1000 -> 0 | J35: =G35*1 -> 0 | K35: =J35+I35+H35 -> 0 | L35: pcs | M35: 39169092 | N35: Kg
A36: =A35+1 -> 26 | B36: PUROTEKUTA 1422L (55788-42050) | C36: 0.234 | D36: 24 | E36: 500 | F36: =_xlfn.IFNA(VLOOKUP(B36,'PACKING LIST'!$B$35:$F$54,5,FALSE),0) -> 0 | G36: =ROUNDUP(F36/E36,0) -> 0 | H36: =F36*D36/1000 -> 0 | J36: =G36*1 -> 0 | K36: =J36+I36+H36 -> 0 | L36: pcs | M36: 39169092 | N36: Kg | P36: =263636+165000 -> 428636
B37: PUROTEKUTA 55788-TOA0010 | C37: 0.224 | D37: 24 | E37: 500 | F37: =_xlfn.IFNA(VLOOKUP(B37,'PACKING LIST'!$B$35:$F$54,5,FALSE),0) -> 0 | G37: =ROUNDUP(F37/E37,0) -> 0 | H37: =F37*D37/1000 -> 0 | J37: =G37*1 -> 0 | K37: =J37+I37+H37 -> 0 | L37: pcs | M37: 39169092 | N37: Kg
B38: PUROTEKUTA 55788-TOA020 | C38: 0.224 | D38: 24 | E38: 500 | F38: =_xlfn.IFNA(VLOOKUP(B38,'PACKING LIST'!$B$35:$F$54,5,FALSE),0) -> 0 | G38: =ROUNDUP(F38/E38,0) -> 0 | H38: =F38*D38/1000 -> 0 | J38: =G38*1 -> 0 | K38: =J38+I38+H38 -> 0 | L38: pcs | M38: 39169092 | N38: Kg
A39: =A36+1 -> 27 | B39: PUROTEKUTA 1383L OK100 | C39: 0.228 | D39: 21.7 | E39: 500 | F39: =_xlfn.IFNA(VLOOKUP(B39,'PACKING LIST'!$B$35:$F$54,5,FALSE),0) -> 0 | G39: =ROUNDUP(F39/E39,0) -> 0 | H39: =F39*D39/1000 -> 0 | J39: =G39*1 -> 0 | K39: =J39+I39+H39 -> 0 | L39: pcs | M39: 39169092 | N39: Kg
A40: =A39+1 -> 28 | B40: PUROTEKUTA 2A4P1-018G | C40: 0.229 | D40: 22.1 | E40: 500 | F40: =_xlfn.IFNA(VLOOKUP(B40,'PACKING LIST'!$B$35:$F$54,5,FALSE),0) -> 0 | G40: =ROUNDUP(F40/E40,0) -> 0 | H40: =F40*D40/1000 -> 0 | J40: =G40*1 -> 0 | K40: =J40+I40+H40 -> 0 | L40: pcs | M40: 39169092 | N40: Kg
A41: =A40+1 -> 29 | B41: PUROTEKUTA 55788-48080 | C41: 0.251 | D41: 25 | E41: 500 | F41: =_xlfn.IFNA(VLOOKUP(B41,'PACKING LIST'!$B$35:$F$54,5,FALSE),0) -> 0 | G41: =ROUNDUP(F41/E41,0) -> 0 | H41: =F41*D41/1000 -> 0 | J41: =G41*1 -> 0 | K41: =J41+I41+H41 -> 0 | L41: pcs | M41: 39169092 | N41: Kg
...
